Workbook

Sheet Raw Data
A1: Boston House Prediction Dataset — Raw Data
A2: CRIM | B2: ZN | C2: INDUS | D2: CHAS | E2: NOX | F2: RM | G2: AGE | H2: DIS | I2: RAD | J2: TAX | K2: PTRATIO | L2: B | M2: LSTAT | N2: PRICE
A3: Crime Rate | B3: Residential Zone % | C3: Industrial Area % | D3: Charles River (1=Yes) | E3: NOX Conc. | F3: Avg Rooms | G3: Age % | H3: Distance to Jobs | I3: Highway Access | J3: Tax Rate | K3: Pupil-Teacher Ratio | L3: B Index | M3: Lower Status % | N3: Price ($000s)
A4: 0.00632 | B4: 18 | C4: 2.31 | D4: 0 | E4: 0.538 | F4: 6.575 | G4: 65.2 | H4: 4.09 | I4: 1 | J4: 296 | K4: 15.3 | L4: 396.9 | M4: 4.98 | N4: 24
A5: 0.02731 | B5: 0 | C5: 7.07 | D5: 0 | E5: 0.469 | F5: 6.421 | G5: 78.9 | H5: 4.9671 | I5: 2 | J5: 242 | K5: 17.8 | L5: 396.9 | M5: 9.14 | N5: 21.6
A6: 0.02729 | B6: 0 | C6: 7.07 | D6: 0 | E6: 0.469 | F6: 7.185 | G6: 61.1 | H6: 4.9671 | I6: 2 | J6: 242 | K6: 17.8 | L6: 392.83 | M6: 4.03 | N6: 34.7
A7: 0.03237 | B7: 0 | C7: 2.18 | D7: 0 | E7: 0.458 | F7: 6.998 | G7: 45.8 | H7: 6.0622 | I7: 3 | J7: 222 | K7: 18.7 | L7: 394.63 | M7: 2.94 | N7: 33.4
A8: 0.06905 | B8: 0 | C8: 2.18 | D8: 0 | E8: 0.458 | F8: 7.147 | G8: 54.2 | H8: 6.0622 | I8: 3 | J8: 222 | K8: 18.7 | L8: 396.9 | M8: 5.33 | N8: 36.2
A9: 0.02985 | B9: 0 | C9: 2.18 | D9: 0 | E9: 0.458 | F9: 6.43 | G9: 58.7 | H9: 6.0622 | I9: 3 | J9: 222 | K9: 18.7 | L9: 394.12 | M9: 5.21 | N9: 28.7
A10: 0.08829 | B10: 12.5 | C10: 7.87 | D10: 0 | E10: 0.524 | F10: 6.012 | G10: 66.6 | H10: 5.5605 | I10: 5 | J10: 311 | K10: 15.2 | L10: 395.6 | M10: 12.43 | N10: 22.9
A11: 0.14455 | B11: 12.5 | C11: 7.87 | D11: 0 | E11: 0.524 | F11: 6.172 | G11: 96.1 | H11: 5.9505 | I11: 5 | J11: 311 | K11: 15.2 | L11: 396.9 | M11: 19.15 | N11: 27.1
A12: 0.21124 | B12: 12.5 | C12: 7.87 | D12: 0 | E12: 0.524 | F12: 5.631 | G12: 100 | H12: 6.0821 | I12: 5 | J12: 311 | K12: 15.2 | L12: 386.63 | M12: 29.93 | N12: 16.5
A13: 0.17004 | B13: 12.5 | C13: 7.87 | D13: 0 | E13: 0.524 | F13: 6.004 | G13: 85.9 | H13: 6.5921 | I13: 5 | J13: 311 | K13: 15.2 | L13: 386.71 | M13: 17.1 | N13: 18.9
A14: 0.22489 | B14: 12.5 | C14: 7.87 | D14: 0 | E14: 0.524 | F14: 6.377 | G14: 94.3 | H14: 6.3467 | I14: 5 | J14: 311 | K14: 15.2 | L14: 392.52 | M14: 20.45 | N14: 15
A15: 0.11747 | B15: 12.5 | C15: 7.87 | D15: 0 | E15: 0.524 | F15: 6.009 | G15: 82.9 | H15: 6.2267 | I15: 5 | J15: 311 | K15: 15.2 | L15: 396.9 | M15: 13.27 | N15: 18.9
... A370: 3.69695 | B370: 0 | C370: 18.1 | D370: 0 | E370: 0.718 | F370: 4.963 | G370: 91.4 | H370: 1.7523 | I370: 24 | J370: 666 | K370: 20.2 | L370: 316.03 | M370: 14 | N370: 21.9
A371: 0 | B371: 18.1 | C371: 0 | D371: 0.631 | E371: 3.863 | F371: 100 | G371: 1.5106 | H371: 24 | I371: 666 | J371: 20.2 | K371: 131.42 | L371: 13.33 | M371: 23.1
A372: 4.89822 | B372: 0 | C372: 18.1 | D372: 0 | E372: 0.631 | F372: 4.97 | G372: 100 | H372: 1.3325 | I372: 24 | J372: 666 | K372: 20.2 | L372: 375.52 | M372: 3.26 | N372: 50
A373: 5.66998 | B373: 0 | C373: 18.1 | D373: 1 | E373: 0.631 | F373: 6.683 | G373: 96.8 | H373: 1.3567 | I373: 24 | J373: 666 | K373: 20.2 | L373: 375.33 | M373: 3.73 | N373: 50
A374: 6.53876 | B374: 0 | C374: 18.1 | D374: 1 | E374: 0.631 | F374: 7.016 | G374: 97.5 | H374: 1.2024 | I374: 24 | J374: 666 | K374: 20.2 | L374: 392.05 | M374: 2.96 | N374: 50
A375: 9.2323 | B375: 0 | C375: 18.1 | D375: 0 | E375: 0.631 | F375: 6.216 | G375: 100 | H375: 1.1691 | I375: 24 | J375: 666 | K375: 20.2 | L375: 366.15 | M375: 9.53 | N375: 50
A376: 8.26725 | B376: 0 | C376: 18.1 | D376: 1 | E376: 0.668 | F376: 5.875 | G376: 89.6 | H376: 1.1296 | I376: 24 | J376: 666 | K376: 20.2 | L376: 347.88 | M376: 8.88 | N376: 50
A377: 0 | B377: 18.1 | C377: 0 | D377: 0.668 | E377: 4.906 | F377: 100 | G377: 1.1742 | H377: 24 | I377: 666 | J377: 20.2 | K377: 396.9 | L377: 34.77 | M377: 13.8
A378: 0 | B378: 18.1 | C378: 0 | D378: 0.668 | E378: 4.138 | F378: 100 | G378: 1.137 | H378: 24 | I378: 666 | J378: 20.2 | K378: 396.9 | L378: 37.97 | M378: 13.8
A379: 0 | B379: 18.1 | C379: 0 | D379: 0.671 | E379: 7.313 | F379: 97.9 | G379: 1.3163 | H379: 24 | I379: 666 | J379: 20.2 | K379: 396.9 | L379: 13.44 | M379: 15
A380: 0 | B380: 18.1 | C380: 0 | D380: 0.671 | E380: 6.649 | F380: 93.3 | G380: 1.3449 | H380: 24 | I380: 666 | J380: 20.2 | K380: 363.02 | L380: 23.24 | M380: 13.9
A381: 9.82349 | B381: 0 | C381: 18.1 | D381: 0 | E381: 0.671 | F381: 6.794 | G381: 98.8 | H381: 1.358 | I381: 24 | J381: 666 | K381: 20.2 | L381: 396.9 | M381: 21.24 | N381: 13.3
A382: 0 | B382: 18.1 | C382: 0 | D382: 0.671 | E382: 6.38 | F382: 96.2 | G382: 1.3861 | H382: 24 | I382: 666 | J382: 20.2 | K382: 396.9 | L382: 23.69 | M382: 13.1
A383: 0 | B383: 18.1 | C383: 0 | D383: 0.671 | E383: 6.223 | F383: 100 | G383: 1.3861 | H383: 24 | I383: 666 | J383: 20.2 | K383: 393.74 | L383: 21.78 | M383: 10.2
A384: 0 | B384: 18.1 | C384: 0 | D384: 0.671 | E384: 6.968 | F384: 91.9 | G384: 1.4165 | H384: 24 | I384: 666 | J384: 20.2 | K384: 396.9 | L384: 17.21 | M384: 10.4
A385: 0 | B385: 18.1 | C385: 0 | D385: 0.671 | E385: 6.545 | F385: 99.1 | G385: 1.5192 | H385: 24 | I385: 666 | J385: 20.2 | K385: 396.9 | L385: 21.08 | M385: 10.9
A386: 9.18702 | B386: 0 | C386: 18.1 | D386: 0 | E386: 0.7 | F386: 5.536 | G386: 100 | H386: 1.5804 | I386: 24 | J386: 666 | K386: 20.2 | L386: 396.9 | M386: 23.6 | N386: 11.3
A387: 7.99248 | B387: 0 | C387: 18.1 | D387: 0 | E387: 0.7 | F387: 5.52 | G387: 100 | H387: 1.5331 | I387: 24 | J387: 666 | K387: 20.2 | L387: 396.9 | M387: 24.56 | N387: 12.3
A388: 0 | B388: 18.1 | C388: 0 | D388: 0.7 | E388: 4.368 | F388: 91.2 | G388: 1.4395 | H388: 24 | I388: 666 | J388: 20.2 | K388: 285.83 | L388: 30.63 | M388: 8.8
A389: 0 | B389: 18.1 | C389: 0 | D389: 0.7 | E389: 5.277 | F389: 98.1 | G389: 1.4261 | H389: 24 | I389: 666 | J389: 20.2 | K389: 396.9 | L389: 30.81 | M389: 7.2
A390: 0 | B390: 18.1 | C390: 0 | D390: 0.7 | E390: 4.652 | F390: 100 | G390: 1.4672 | H390: 24 | I390: 666 | J390: 20.2 | K390: 396.9 | L390: 28.28 | M390: 10.5
A391: 0 | B391: 18.1 | C391: 0 | D391: 0.7 | E391: 5 | F391: 89.5 | G391: 1.5184 | H391: 24 | I391: 666 | J391: 20.2 | K391: 396.9 | L391: 31.99 | M391: 7.4
A392: 0 | B392: 18.1 | C392: 0 | D392: 0.7 | E392: 4.88 | F392: 100 | G392: 1.5895 | H392: 24 | I392: 666 | J392: 20.2 | K392: 372.92 | L392: 30.62 | M392: 10.2
A393: 8.15174 | B393: 0 | C393: 18.1 | D393: 0 | E393: 0.7 | F393: 5.39 | G393: 98.9 | H393: 1.7281 | I393: 24 | J393: 666 | K393: 20.2 | L393: 396.9 | M393: 20.85 | N393: 11.5
A394: 6.96215 | B394: 0 | C394: 18.1 | D394: 0 | E394: 0.7 | F394: 5.713 | G394: 97 | H394: 1.9265 | I394: 24 | J394: 666 | K394: 20.2 | L394: 394.43 | M394: 17.11 | N394: 15.1
...

Sheet Task 1 - Logical Functions
A1: Task 1 : Logical & Conditional Functions - House Price Analysis
A2: Row# | B2: Price ($000s) | C2: Avg Rooms | D2: Crime Rate | E2: IF: Price Category | F2: IFS:Detailed Tier | G2: AND: Affordable & Spacious | H2: OR :Desirable Location | I2: NOT: High Crime? | J2: Nested IF: Investment Grade
A3: 1 | B3: ='Raw Data'!N4 -> 24 | C3: ='Raw Data'!F4 -> 6.575 | D3: ='Raw Data'!A4 -> 0.00632 | E3: =IF(B3<=15,"Low",IF(B3<=25,"Medium","High")) -> Medium | F3: =IF(B3<=10,"Very Low",IF(B3<=20,"Low",IF(B3<=30,"Medium",IF(B3<=40,"High","Very High")))) -> Medium | G3: =IF(AND(B3<=22,C3>=6),"Yes - Affordable & Spacious","No") -> No | H3: =IF(OR('Raw Data'!D4=1,D3<0.1),"Yes - Desirable","No") -> Yes - Desirable | I3: =IF(NOT(D3>=1),"Safe Area","High Crime") -> Safe Area | J3: =IF(B3>=35,IF(D3<0.5,"Grade A - Premium","Grade B - Good"),IF(B3>=20,"Grade C - Average","Grade D - Low Value")) -> Grade C - Average
A4: 2 | B4: ='Raw Data'!N5 -> 21.6 | C4: ='Raw Data'!F5 -> 6.421 | D4: ='Raw Data'!A5 -> 0.02731 | E4: =IF(B4<=15,"Low",IF(B4<=25,"Medium","High")) -> Medium | F4: =IF(B4<=10,"Very Low",IF(B4<=20,"Low",IF(B4<=30,"Medium",IF(B4<=40,"High","Very High")))) -> Medium | G4: =IF(AND(B4<=22,C4>=6),"Yes - Affordable & Spacious","No") -> Yes - Affordable & Spacious | H4: =IF(OR('Raw Data'!D5=1,D4<0.1),"Yes - Desirable","No") -> Yes - Desirable | I4: =IF(NOT(D4>=1),"Safe Area","High Crime") -> Safe Area | J4: =IF(B4>=35,IF(D4<0.5,"Grade A - Premium","Grade B - Good"),IF(B4>=20,"Grade C - Average","Grade D - Low Value")) -> Grade C - Average
A5: 3 | B5: ='Raw Data'!N6 -> 34.7 | C5: ='Raw Data'!F6 -> 7.185 | D5: ='Raw Data'!A6 -> 0.02729 | E5: =IF(B5<=15,"Low",IF(B5<=25,"Medium","High")) -> High | F5: =IF(B5<=10,"Very Low",IF(B5<=20,"Low",IF(B5<=30,"Medium",IF(B5<=40,"High","Very High")))) -> High | G5: =IF(AND(B5<=22,C5>=6),"Yes - Affordable & Spacious","No") -> No | H5: =IF(OR('Raw Data'!D6=1,D5<0.1),"Yes - Desirable","No") -> Yes - Desirable | I5: =IF(NOT(D5>=1),"Safe Area","High Crime") -> Safe Area | J5: =IF(B5>=35,IF(D5<0.5,"Grade A - Premium","Grade B - Good"),IF(B5>=20,"Grade C - Average","Grade D - Low Value")) -> Grade C - Average
A6: 4 | B6: ='Raw Data'!N7 -> 33.4 | C6: ='Raw Data'!F7 -> 6.998 | D6: ='Raw Data'!A7 -> 0.03237 | E6: =IF(B6<=15,"Low",IF(B6<=25,"Medium","High")) -> High | F6: =IF(B6<=10,"Very Low",IF(B6<=20,"Low",IF(B6<=30,"Medium",IF(B6<=40,"High","Very High")))) -> High | G6: =IF(AND(B6<=22,C6>=6),"Yes - Affordable & Spacious","No") -> No | H6: =IF(OR('Raw Data'!D7=1,D6<0.1),"Yes - Desirable","No") -> Yes - Desirable | I6: =IF(NOT(D6>=1),"Safe Area","High Crime") -> Safe Area | J6: =IF(B6>=35,IF(D6<0.5,"Grade A - Premium","Grade B - Good"),IF(B6>=20,"Grade C - Average","Grade D - Low Value")) -> Grade C - Average
A7: 5 | B7: ='Raw Data'!N8 -> 36.2 | C7: ='Raw Data'!F8 -> 7.147 | D7: ='Raw Data'!A8 -> 0.06905 | E7: =IF(B7<=15,"Low",IF(B7<=25,"Medium","High")) -> High | F7: =IF(B7<=10,"Very Low",IF(B7<=20,"Low",IF(B7<=30,"Medium",IF(B7<=40,"High","Very High")))) -> High | G7: =IF(AND(B7<=22,C7>=6),"Yes - Affordable & Spacious","No") -> No | H7: =IF(OR('Raw Data'!D8=1,D7<0.1),"Yes - Desirable","No") -> Yes - Desirable | I7: =IF(NOT(D7>=1),"Safe Area","High Crime") -> Safe Area | J7: =IF(B7>=35,IF(D7<0.5,"Grade A - Premium","Grade B - Good"),IF(B7>=20,"Grade C - Average","Grade D - Low Value")) -> Grade A - Premium
A8: 6 | B8: ='Raw Data'!N9 -> 28.7 | C8: ='Raw Data'!F9 -> 6.43 | D8: ='Raw Data'!A9 -> 0.02985 | E8: =IF(B8<=15,"Low",IF(B8<=25,"Medium","High")) -> High | F8: =IF(B8<=10,"Very Low",IF(B8<=20,"Low",IF(B8<=30,"Medium",IF(B8<=40,"High","Very High")))) -> Medium | G8: =IF(AND(B8<=22,C8>=6),"Yes - Affordable & Spacious","No") -> No | H8: =IF(OR('Raw Data'!D9=1,D8<0.1),"Yes - Desirable","No") -> Yes - Desirable | I8: =IF(NOT(D8>=1),"Safe Area","High Crime") -> Safe Area | J8: =IF(B8>=35,IF(D8<0.5,"Grade A - Premium","Grade B - Good"),IF(B8>=20,"Grade C - Average","Grade D - Low Value")) -> Grade C - Average
A9: 7 | B9: ='Raw Data'!N10 -> 22.9 | C9: ='Raw Data'!F10 -> 6.012 | D9: ='Raw Data'!A10 -> 0.08829 | E9: =IF(B9<=15,"Low",IF(B9<=25,"Medium","High")) -> Medium | F9: =IF(B9<=10,"Very Low",IF(B9<=20,"Low",IF(B9<=30,"Medium",IF(B9<=40,"High","Very High")))) -> Medium | G9: =IF(AND(B9<=22,C9>=6),"Yes - Affordable & Spacious","No") -> No | H9: =IF(OR('Raw Data'!D10=1,D9<0.1),"Yes - Desirable","No") -> Yes - Desirable | I9: =IF(NOT(D9>=1),"Safe Area","High Crime") -> Safe Area | J9: =IF(B9>=35,IF(D9<0.5,"Grade A - Premium","Grade B - Good"),IF(B9>=20,"Grade C - Average","Grade D - Low Value")) -> Grade C - Average
A10: 8 | B10: ='Raw Data'!N11 -> 27.1 | C10: ='Raw Data'!F11 -> 6.172 | D10: ='Raw Data'!A11 -> 0.14455 | E10: =IF(B10<=15,"Low",IF(B10<=25,"Medium","High")) -> High | F10: =IF(B10<=10,"Very Low",IF(B10<=20,"Low",IF(B10<=30,"Medium",IF(B10<=40,"High","Very High")))) -> Medium | G10: =IF(AND(B10<=22,C10>=6),"Yes - Affordable & Spacious","No") -> No | H10: =IF(OR('Raw Data'!D11=1,D10<0.1),"Yes - Desirable","No") -> No | I10: =IF(NOT(D10>=1),"Safe Area","High Crime") -> Safe Area | J10: =IF(B10>=35,IF(D10<0.5,"Grade A - Premium","Grade B - Good"),IF(B10>=20,"Grade C - Average","Grade D - Low Value")) -> Grade C - Average
A11: 9 | B11: ='Raw Data'!N12 -> 16.5 | C11: ='Raw Data'!F12 -> 5.631 | D11: ='Raw Data'!A12 -> 0.21124 | E11: =IF(B11<=15,"Low",IF(B11<=25,"Medium","High")) -> Medium | F11: =IF(B11<=10,"Very Low",IF(B11<=20,"Low",IF(B11<=30,"Medium",IF(B11<=40,"High","Very High")))) -> Low | G11: =IF(AND(B11<=22,C11>=6),"Yes - Affordable & Spacious","No") -> No | H11: =IF(OR('Raw Data'!D12=1,D11<0.1),"Yes - Desirable","No") -> No | I11: =IF(NOT(D11>=1),"Safe Area","High Crime") -> Safe Area | J11: =IF(B11>=35,IF(D11<0.5,"Grade A - Premium","Grade B - Good"),IF(B11>=20,"Grade C - Average","Grade D - Low Value")) -> Grade D - Low Value
A12: 10 | B12: ='Raw Data'!N13 -> 18.9 | C12: ='Raw Data'!F13 -> 6.004 | D12: ='Raw Data'!A13 -> 0.17004 | E12: =IF(B12<=15,"Low",IF(B12<=25,"Medium","High")) -> Medium | F12: =IF(B12<=10,"Very Low",IF(B12<=20,"Low",IF(B12<=30,"Medium",IF(B12<=40,"High","Very High")))) -> Low | G12: =IF(AND(B12<=22,C12>=6),"Yes - Affordable & Spacious","No") -> Yes - Affordable & Spacious | H12: =IF(OR('Raw Data'!D13=1,D12<0.1),"Yes - Desirable","No") -> No | I12: =IF(NOT(D12>=1),"Safe Area","High Crime") -> Safe Area | J12: =IF(B12>=35,IF(D12<0.5,"Grade A - Premium","Grade B - Good"),IF(B12>=20,"Grade C - Average","Grade D - Low Value")) -> Grade D - Low Value
A13: 11 | B13: ='Raw Data'!N14 -> 15 | C13: ='Raw Data'!F14 -> 6.377 | D13: ='Raw Data'!A14 -> 0.22489 | E13: =IF(B13<=15,"Low",IF(B13<=25,"Medium","High")) -> Low | F13: =IF(B13<=10,"Very Low",IF(B13<=20,"Low",IF(B13<=30,"Medium",IF(B13<=40,"High","Very High")))) -> Low | G13: =IF(AND(B13<=22,C13>=6),"Yes - Affordable & Spacious","No") -> Yes - Affordable & Spacious | H13: =IF(OR('Raw Data'!D14=1,D13<0.1),"Yes - Desirable","No") -> No | I13: =IF(NOT(D13>=1),"Safe Area","High Crime") -> Safe Area | J13: =IF(B13>=35,IF(D13<0.5,"Grade A - Premium","Grade B - Good"),IF(B13>=20,"Grade C - Average","Grade D - Low Value")) -> Grade D - Low Value
A14: 12 | B14: ='Raw Data'!N15 -> 18.9 | C14: ='Raw Data'!F15 -> 6.009 | D14: ='Raw Data'!A15 -> 0.11747 | E14: =IF(B14<=15,"Low",IF(B14<=25,"Medium","High")) -> Medium | F14: =IF(B14<=10,"Very Low",IF(B14<=20,"Low",IF(B14<=30,"Medium",IF(B14<=40,"High","Very High")))) -> Low | G14: =IF(AND(B14<=22,C14>=6),"Yes - Affordable & Spacious","No") -> Yes - Affordable & Spacious | H14: =IF(OR('Raw Data'!D15=1,D14<0.1),"Yes - Desirable","No") -> No | I14: =IF(NOT(D14>=1),"Safe Area","High Crime") -> Safe Area | J14: =IF(B14>=35,IF(D14<0.5,"Grade A - Premium","Grade B - Good"),IF(B14>=20,"Grade C - Average","Grade D - Low Value")) -> Grade D - Low Value
... A508: 506 | B508: ='Raw Data'!N509 -> 11.9 | C508: ='Raw Data'!F509 -> 6.03 | D508: ='Raw Data'!A509 -> 0.04741 | E508: =IF(B508<=15,"Low",IF(B508<=25,"Medium","High")) -> Low | F508: =IF(B508<=10,"Very Low",IF(B508<=20,"Low",IF(B508<=30,"Medium",IF(B508<=40,"High","Very High")))) -> Low | G508: =IF(AND(B508<=22,C508>=6),"Yes - Affordable & Spacious","No") -> Yes - Affordable & Spacious | H508: =IF(OR('Raw Data'!D509=1,D508<0.1),"Yes - Desirable","No") -> Yes - Desirable | I508: =IF(NOT(D508>=1),"Safe Area","High Crime") -> Safe Area | J508: =IF(B508>=35,IF(D508<0.5,"Grade A - Premium","Grade B - Good"),IF(B508>=20,"Grade C - Average","Grade D - Low Value")) -> Grade D - Low Value

Sheet Task 1 - Error & Special Funcs
A1: Task 1 : CHOOSE, ISERROR, ISBLANK, ISNUMBER - House Data Validation
A2: Row# | B2: Price($000s) | C2: RAD Index | D2: CHOOSE: Highway Category | E2: Price Band | F2: ISNUMBER: Price Valid? | G2: ISBLANK: Missing? | H2: ISERROR: Safe Division
A3: 1 | B3: ='Raw Data'!N4 -> 24 | C3: ='Raw Data'!I4 -> 1 | D3: =CHOOSE(MIN(5,MAX(1,INT(C3/5)+1)),"Very Low Access","Low Access","Medium Access","High Access","Very High Access") -> Very Low Access | E3: =IF(B3<15,"Under $15k",IF(B3<25,"$15-25k",IF(B3<35,"$25-35k",IF(B3<45,"$35-45k","Over $45k")))) -> $15-25k | F3: =IF(ISNUMBER(B3),"Valid Number","Not a Number") -> Valid Number | G3: =IF(ISBLANK(B3),"Missing","Data Present") -> Data Present | H3: =IFERROR(B3/'Raw Data'!A4,"Error: Div by Zero") -> 3797.4684
A4: 2 | B4: ='Raw Data'!N5 -> 21.6 | C4: ='Raw Data'!I5 -> 2 | D4: =CHOOSE(MIN(5,MAX(1,INT(C4/5)+1)),"Very Low Access","Low Access","Medium Access","High Access","Very High Access") -> Very Low Access | E4: =IF(B4<15,"Under $15k",IF(B4<25,"$15-25k",IF(B4<35,"$25-35k",IF(B4<45,"$35-45k","Over $45k")))) -> $15-25k | F4: =IF(ISNUMBER(B4),"Valid Number","Not a Number") -> Valid Number | G4: =IF(ISBLANK(B4),"Missing","Data Present") -> Data Present | H4: =IFERROR(B4/'Raw Data'!A5,"Error: Div by Zero") -> 790.91908
A5: 3 | B5: ='Raw Data'!N6 -> 34.7 | C5: ='Raw Data'!I6 -> 2 | D5: =CHOOSE(MIN(5,MAX(1,INT(C5/5)+1)),"Very Low Access","Low Access","Medium Access","High Access","Very High Access") -> Very Low Access | E5: =IF(B5<15,"Under $15k",IF(B5<25,"$15-25k",IF(B5<35,"$25-35k",IF(B5<45,"$35-45k","Over $45k")))) -> $25-35k | F5: =IF(ISNUMBER(B5),"Valid Number","Not a Number") -> Valid Number | G5: =IF(ISBLANK(B5),"Missing","Data Present") -> Data Present | H5: =IFERROR(B5/'Raw Data'!A6,"Error: Div by Zero") -> 1271.528
A6: 4 | B6: ='Raw Data'!N7 -> 33.4 | C6: ='Raw Data'!I7 -> 3 | D6: =CHOOSE(MIN(5,MAX(1,INT(C6/5)+1)),"Very Low Access","Low Access","Medium Access","High Access","Very High Access") -> Very Low Access | E6: =IF(B6<15,"Under $15k",IF(B6<25,"$15-25k",IF(B6<35,"$25-35k",IF(B6<45,"$35-45k","Over $45k")))) -> $25-35k | F6: =IF(ISNUMBER(B6),"Valid Number","Not a Number") -> Valid Number | G6: =IF(ISBLANK(B6),"Missing","Data Present") -> Data Present | H6: =IFERROR(B6/'Raw Data'!A7,"Error: Div by Zero") -> 1031.8196
A7: 5 | B7: ='Raw Data'!N8 -> 36.2 | C7: ='Raw Data'!I8 -> 3 | D7: =CHOOSE(MIN(5,MAX(1,INT(C7/5)+1)),"Very Low Access","Low Access","Medium Access","High Access","Very High Access") -> Very Low Access | E7: =IF(B7<15,"Under $15k",IF(B7<25,"$15-25k",IF(B7<35,"$25-35k",IF(B7<45,"$35-45k","Over $45k")))) -> $35-45k | F7: =IF(ISNUMBER(B7),"Valid Number","Not a Number") -> Valid Number | G7: =IF(ISBLANK(B7),"Missing","Data Present") -> Data Present | H7: =IFERROR(B7/'Raw Data'!A8,"Error: Div by Zero") -> 524.25778
A8: 6 | B8: ='Raw Data'!N9 -> 28.7 | C8: ='Raw Data'!I9 -> 3 | D8: =CHOOSE(MIN(5,MAX(1,INT(C8/5)+1)),"Very Low Access","Low Access","Medium Access","High Access","Very High Access") -> Very Low Access | E8: =IF(B8<15,"Under $15k",IF(B8<25,"$15-25k",IF(B8<35,"$25-35k",IF(B8<45,"$35-45k","Over $45k")))) -> $25-35k | F8: =IF(ISNUMBER(B8),"Valid Number","Not a Number") -> Valid Number | G8: =IF(ISBLANK(B8),"Missing","Data Present") -> Data Present | H8: =IFERROR(B8/'Raw Data'!A9,"Error: Div by Zero") -> 961.47404
A9: 7 | B9: ='Raw Data'!N10 -> 22.9 | C9: ='Raw Data'!I10 -> 5 | D9: =CHOOSE(MIN(5,MAX(1,INT(C9/5)+1)),"Very Low Access","Low Access","Medium Access","High Access","Very High Access") -> Low Access | E9: =IF(B9<15,"Under $15k",IF(B9<25,"$15-25k",IF(B9<35,"$25-35k",IF(B9<45,"$35-45k","Over $45k")))) -> $15-25k | F9: =IF(ISNUMBER(B9),"Valid Number","Not a Number") -> Valid Number | G9: =IF(ISBLANK(B9),"Missing","Data Present") -> Data Present | H9: =IFERROR(B9/'Raw Data'!A10,"Error: Div by Zero") -> 259.37252
A10: 8 | B10: ='Raw Data'!N11 -> 27.1 | C10: ='Raw Data'!I11 -> 5 | D10: =CHOOSE(MIN(5,MAX(1,INT(C10/5)+1)),"Very Low Access","Low Access","Medium Access","High Access","Very High Access") -> Low Access | E10: =IF(B10<15,"Under $15k",IF(B10<25,"$15-25k",IF(B10<35,"$25-35k",IF(B10<45,"$35-45k","Over $45k")))) -> $25-35k | F10: =IF(ISNUMBER(B10),"Valid Number","Not a Number") -> Valid Number | G10: =IF(ISBLANK(B10),"Missing","Data Present") -> Data Present | H10: =IFERROR(B10/'Raw Data'!A11,"Error: Div by Zero") -> 187.47838
A11: 9 | B11: ='Raw Data'!N12 -> 16.5 | C11: ='Raw Data'!I12 -> 5 | D11: =CHOOSE(MIN(5,MAX(1,INT(C11/5)+1)),"Very Low Access","Low Access","Medium Access","High Access","Very High Access") -> Low Access | E11: =IF(B11<15,"Under $15k",IF(B11<25,"$15-25k",IF(B11<35,"$25-35k",IF(B11<45,"$35-45k","Over $45k")))) -> $15-25k | F11: =IF(ISNUMBER(B11),"Valid Number","Not a Number") -> Valid Number | G11: =IF(ISBLANK(B11),"Missing","Data Present") -> Data Present | H11: =IFERROR(B11/'Raw Data'!A12,"Error: Div by Zero") -> 78.110206
A12: 10 | B12: ='Raw Data'!N13 -> 18.9 | C12: ='Raw Data'!I13 -> 5 | D12: =CHOOSE(MIN(5,MAX(1,INT(C12/5)+1)),"Very Low Access","Low Access","Medium Access","High Access","Very High Access") -> Low Access | E12: =IF(B12<15,"Under $15k",IF(B12<25,"$15-25k",IF(B12<35,"$25-35k",IF(B12<45,"$35-45k","Over $45k")))) -> $15-25k | F12: =IF(ISNUMBER(B12),"Valid Number","Not a Number") -> Valid Number | G12: =IF(ISBLANK(B12),"Missing","Data Present") -> Data Present | H12: =IFERROR(B12/'Raw Data'!A13,"Error: Div by Zero") -> 111.15032
A13: 11 | B13: ='Raw Data'!N14 -> 15 | C13: ='Raw Data'!I14 -> 5 | D13: =CHOOSE(MIN(5,MAX(1,INT(C13/5)+1)),"Very Low Access","Low Access","Medium Access","High Access","Very High Access") -> Low Access | E13: =IF(B13<15,"Under $15k",IF(B13<25,"$15-25k",IF(B13<35,"$25-35k",IF(B13<45,"$35-45k","Over $45k")))) -> $15-25k | F13: =IF(ISNUMBER(B13),"Valid Number","Not a Number") -> Valid Number | G13: =IF(ISBLANK(B13),"Missing","Data Present") -> Data Present | H13: =IFERROR(B13/'Raw Data'!A14,"Error: Div by Zero") -> 66.699275
A14: 12 | B14: ='Raw Data'!N15 -> 18.9 | C14: ='Raw Data'!I15 -> 5 | D14: =CHOOSE(MIN(5,MAX(1,INT(C14/5)+1)),"Very Low Access","Low Access","Medium Access","High Access","Very High Access") -> Low Access | E14: =IF(B14<15,"Under $15k",IF(B14<25,"$15-25k",IF(B14<35,"$25-35k",IF(B14<45,"$35-45k","Over $45k")))) -> $15-25k | F14: =IF(ISNUMBER(B14),"Valid Number","Not a Number") -> Valid Number | G14: =IF(ISBLANK(B14),"Missing","Data Present") -> Data Present | H14: =IFERROR(B14/'Raw Data'!A15,"Error: Div by Zero") -> 160.89214
... A508: 506 | B508: ='Raw Data'!N509 -> 11.9 | C508: ='Raw Data'!I509 -> 1 | D508: =CHOOSE(MIN(5,MAX(1,INT(C508/5)+1)),"Very Low Access","Low Access","Medium Access","High Access","Very High Access") -> Very Low Access | E508: =IF(B508<15,"Under $15k",IF(B508<25,"$15-25k",IF(B508<35,"$25-35k",IF(B508<45,"$35-45k","Over $45k")))) -> Under $15k | F508: =IF(ISNUMBER(B508),"Valid Number","Not a Number") -> Valid Number | G508: =IF(ISBLANK(B508),"Missing","Data Present") -> Data Present | H508: =IFERROR(B508/'Raw Data'!A509,"Error: Div by Zero") -> 251.0019

Sheet Task 2 - Lookup Functions
A1: Task 2 : Advanced Lookup & Reference Functions - House Price Analysis
A2: Row# | B2: Price($000s) | C2: Crime Rate | D2: VLOOKUP: Price by Row | E2: XLOOKUP: Crime by Price | F2: INDEX-MATCH: Crime at Max Price | G2: INDEX-MATCH:Rooms at Min Price
A3: 1 | B3: ='Raw Data'!N4 -> 24 | C3: ='Raw Data'!A4 -> 0.00632 | D3: =VLOOKUP(B3,'Raw Data'!$N$4:$N$508,1,FALSE) -> 24 | E3: =_xlfn.XLOOKUP(B3,'Raw Data'!$N$4:$N$509,'Raw Data'!$A$4:$A$509,"Not Found") -> 0.00632 | F3: =INDEX('Raw Data'!$A$4:$A$508,MATCH(MAX('Raw Data'!$N$4:$N$508),'Raw Data'!$N$4:$N$508,0)) -> 1.46336 | G3: =INDEX('Raw Data'!$F$4:$F$508,MATCH(MIN('Raw Data'!$N$4:$N$508),'Raw Data'!$N$4:$N$508,0)) -> 5.852
A4: 2 | B4: ='Raw Data'!N5 -> 21.6 | C4: ='Raw Data'!A5 -> 0.02731 | D4: =VLOOKUP(B4,'Raw Data'!$N$4:$N$508,1,FALSE) -> 21.6 | E4: =_xlfn.XLOOKUP(B4,'Raw Data'!$N$4:$N$509,'Raw Data'!$A$4:$A$509,"Not Found") -> 0.02731 | F4: =INDEX('Raw Data'!$A$4:$A$508,MATCH(MAX('Raw Data'!$N$4:$N$508),'Raw Data'!$N$4:$N$508,0)) -> 1.46336 | G4: =INDEX('Raw Data'!$F$4:$F$508,MATCH(MIN('Raw Data'!$N$4:$N$508),'Raw Data'!$N$4:$N$508,0)) -> 5.852
A5: 3 | B5: ='Raw Data'!N6 -> 34.7 | C5: ='Raw Data'!A6 -> 0.02729 | D5: =VLOOKUP(B5,'Raw Data'!$N$4:$N$508,1,FALSE) -> 34.7 | E5: =_xlfn.XLOOKUP(B5,'Raw Data'!$N$4:$N$509,'Raw Data'!$A$4:$A$509,"Not Found") -> 0.02729 | F5: =INDEX('Raw Data'!$A$4:$A$508,MATCH(MAX('Raw Data'!$N$4:$N$508),'Raw Data'!$N$4:$N$508,0)) -> 1.46336 | G5: =INDEX('Raw Data'!$F$4:$F$508,MATCH(MIN('Raw Data'!$N$4:$N$508),'Raw Data'!$N$4:$N$508,0)) -> 5.852
A6: 4 | B6: ='Raw Data'!N7 -> 33.4 | C6: ='Raw Data'!A7 -> 0.03237 | D6: =VLOOKUP(B6,'Raw Data'!$N$4:$N$508,1,FALSE) -> 33.4 | E6: =_xlfn.XLOOKUP(B6,'Raw Data'!$N$4:$N$509,'Raw Data'!$A$4:$A$509,"Not Found") -> 0.03237 | F6: =INDEX('Raw Data'!$A$4:$A$508,MATCH(MAX('Raw Data'!$N$4:$N$508),'Raw Data'!$N$4:$N$508,0)) -> 1.46336 | G6: =INDEX('Raw Data'!$F$4:$F$508,MATCH(MIN('Raw Data'!$N$4:$N$508),'Raw Data'!$N$4:$N$508,0)) -> 5.852
A7: 5 | B7: ='Raw Data'!N8 -> 36.2 | C7: ='Raw Data'!A8 -> 0.06905 | D7: =VLOOKUP(B7,'Raw Data'!$N$4:$N$508,1,FALSE) -> 36.2 | E7: =_xlfn.XLOOKUP(B7,'Raw Data'!$N$4:$N$509,'Raw Data'!$A$4:$A$509,"Not Found") -> 0.06905 | F7: =INDEX('Raw Data'!$A$4:$A$508,MATCH(MAX('Raw Data'!$N$4:$N$508),'Raw Data'!$N$4:$N$508,0)) -> 1.46336 | G7: =INDEX('Raw Data'!$F$4:$F$508,MATCH(MIN('Raw Data'!$N$4:$N$508),'Raw Data'!$N$4:$N$508,0)) -> 5.852
A8: 6 | B8: ='Raw Data'!N9 -> 28.7 | C8: ='Raw Data'!A9 -> 0.02985 | D8: =VLOOKUP(B8,'Raw Data'!$N$4:$N$508,1,FALSE) -> 28.7 | E8: =_xlfn.XLOOKUP(B8,'Raw Data'!$N$4:$N$509,'Raw Data'!$A$4:$A$509,"Not Found") -> 0.02985 | F8: =INDEX('Raw Data'!$A$4:$A$508,MATCH(MAX('Raw Data'!$N$4:$N$508),'Raw Data'!$N$4:$N$508,0)) -> 1.46336 | G8: =INDEX('Raw Data'!$F$4:$F$508,MATCH(MIN('Raw Data'!$N$4:$N$508),'Raw Data'!$N$4:$N$508,0)) -> 5.852
A9: 7 | B9: ='Raw Data'!N10 -> 22.9 | C9: ='Raw Data'!A10 -> 0.08829 | D9: =VLOOKUP(B9,'Raw Data'!$N$4:$N$508,1,FALSE) -> 22.9 | E9: =_xlfn.XLOOKUP(B9,'Raw Data'!$N$4:$N$509,'Raw Data'!$A$4:$A$509,"Not Found") -> 0.08829 | F9: =INDEX('Raw Data'!$A$4:$A$508,MATCH(MAX('Raw Data'!$N$4:$N$508),'Raw Data'!$N$4:$N$508,0)) -> 1.46336 | G9: =INDEX('Raw Data'!$F$4:$F$508,MATCH(MIN('Raw Data'!$N$4:$N$508),'Raw Data'!$N$4:$N$508,0)) -> 5.852
A10: 8 | B10: ='Raw Data'!N11 -> 27.1 | C10: ='Raw Data'!A11 -> 0.14455 | D10: =VLOOKUP(B10,'Raw Data'!$N$4:$N$508,1,FALSE) -> 27.1 | E10: =_xlfn.XLOOKUP(B10,'Raw Data'!$N$4:$N$509,'Raw Data'!$A$4:$A$509,"Not Found") -> 0.14455 | F10: =INDEX('Raw Data'!$A$4:$A$508,MATCH(MAX('Raw Data'!$N$4:$N$508),'Raw Data'!$N$4:$N$508,0)) -> 1.46336 | G10: =INDEX('Raw Data'!$F$4:$F$508,MATCH(MIN('Raw Data'!$N$4:$N$508),'Raw Data'!$N$4:$N$508,0)) -> 5.852
A11: 9 | B11: ='Raw Data'!N12 -> 16.5 | C11: ='Raw Data'!A12 -> 0.21124 | D11: =VLOOKUP(B11,'Raw Data'!$N$4:$N$508,1,FALSE) -> 16.5 | E11: =_xlfn.XLOOKUP(B11,'Raw Data'!$N$4:$N$509,'Raw Data'!$A$4:$A$509,"Not Found") -> 0.21124 | F11: =INDEX('Raw Data'!$A$4:$A$508,MATCH(MAX('Raw Data'!$N$4:$N$508),'Raw Data'!$N$4:$N$508,0)) -> 1.46336 | G11: =INDEX('Raw Data'!$F$4:$F$508,MATCH(MIN('Raw Data'!$N$4:$N$508),'Raw Data'!$N$4:$N$508,0)) -> 5.852
A12: 10 | B12: ='Raw Data'!N13 -> 18.9 | C12: ='Raw Data'!A13 -> 0.17004 | D12: =VLOOKUP(B12,'Raw Data'!$N$4:$N$508,1,FALSE) -> 18.9 | E12: =_xlfn.XLOOKUP(B12,'Raw Data'!$N$4:$N$509,'Raw Data'!$A$4:$A$509,"Not Found") -> 0.17004 | F12: =INDEX('Raw Data'!$A$4:$A$508,MATCH(MAX('Raw Data'!$N$4:$N$508),'Raw Data'!$N$4:$N$508,0)) -> 1.46336 | G12: =INDEX('Raw Data'!$F$4:$F$508,MATCH(MIN('Raw Data'!$N$4:$N$508),'Raw Data'!$N$4:$N$508,0)) -> 5.852
A13: 11 | B13: ='Raw Data'!N14 -> 15 | C13: ='Raw Data'!A14 -> 0.22489 | D13: =VLOOKUP(B13,'Raw Data'!$N$4:$N$508,1,FALSE) -> 15 | E13: =_xlfn.XLOOKUP(B13,'Raw Data'!$N$4:$N$509,'Raw Data'!$A$4:$A$509,"Not Found") -> 0.22489 | F13: =INDEX('Raw Data'!$A$4:$A$508,MATCH(MAX('Raw Data'!$N$4:$N$508),'Raw Data'!$N$4:$N$508,0)) -> 1.46336 | G13: =INDEX('Raw Data'!$F$4:$F$508,MATCH(MIN('Raw Data'!$N$4:$N$508),'Raw Data'!$N$4:$N$508,0)) -> 5.852
A14: 12 | B14: ='Raw Data'!N15 -> 18.9 | C14: ='Raw Data'!A15 -> 0.11747 | D14: =VLOOKUP(B14,'Raw Data'!$N$4:$N$508,1,FALSE) -> 18.9 | E14: =_xlfn.XLOOKUP(B14,'Raw Data'!$N$4:$N$509,'Raw Data'!$A$4:$A$509,"Not Found") -> 0.17004 | F14: =INDEX('Raw Data'!$A$4:$A$508,MATCH(MAX('Raw Data'!$N$4:$N$508),'Raw Data'!$N$4:$N$508,0)) -> 1.46336 | G14: =INDEX('Raw Data'!$F$4:$F$508,MATCH(MIN('Raw Data'!$N$4:$N$508),'Raw Data'!$N$4:$N$508,0)) -> 5.852
... A508: 506 | B508: ='Raw Data'!N509 -> 11.9 | C508: ='Raw Data'!A509 -> 0.04741 | D508: =VLOOKUP(B508,'Raw Data'!$N$4:$N$508,1,FALSE) -> #N/A | E508: =_xlfn.XLOOKUP(B508,'Raw Data'!$N$4:$N$509,'Raw Data'!$A$4:$A$509,"Not Found") -> 0.04741 | F508: =INDEX('Raw Data'!$A$4:$A$508,MATCH(MAX('Raw Data'!$N$4:$N$508),'Raw Data'!$N$4:$N$508,0)) -> 1.46336 | G508: =INDEX('Raw Data'!$F$4:$F$508,MATCH(MIN('Raw Data'!$N$4:$N$508),'Raw Data'!$N$4:$N$508,0)) -> 5.852

Sheet Task 2 - Dynamic Reference
A1: Tak 2: INDIRECT,OFFSET & HLOOKUP - Dynamic Referencing
A2: Row# | B2: Price($000s) | C2: HLOOKUP: Column Header | D2: INDIRECT: Dynamic Reference | E2: OFFSET: Next Row Price | F2: OFFSET: Previous Row Price
A3: 1 | B3: ='Raw Data'!N4 -> 24 | C3: =HLOOKUP("PRICE",'Raw Data'!$A$2:$N$3,2,FALSE) -> Price ($000s) | D3: {=INDIRECT("'Raw Data'!N"&(A3+3))} -> 24 | E3: =IF(A3=506,"End Of Data",OFFSET('Raw Data'!$N$4,A3,0)) -> 21.6 | F3: =IF(A3=1,"Start of Data",OFFSET('Raw Data'!$N$4,A3-2,0)) -> Start of Data
A4: 2 | B4: ='Raw Data'!N5 -> 21.6 | C4: =HLOOKUP("PRICE",'Raw Data'!$A$2:$N$3,2,FALSE) -> Price ($000s) | D4: {=INDIRECT("'Raw Data'!N"&(A4+3))} -> 21.6 | E4: =IF(A4=506,"End Of Data",OFFSET('Raw Data'!$N$4,A4,0)) -> 34.7 | F4: =IF(A4=1,"Start of Data",OFFSET('Raw Data'!$N$4,A4-2,0)) -> 24
A5: 3 | B5: ='Raw Data'!N6 -> 34.7 | C5: =HLOOKUP("PRICE",'Raw Data'!$A$2:$N$3,2,FALSE) -> Price ($000s) | D5: {=INDIRECT("'Raw Data'!N"&(A5+3))} -> 34.7 | E5: =IF(A5=506,"End Of Data",OFFSET('Raw Data'!$N$4,A5,0)) -> 33.4 | F5: =IF(A5=1,"Start of Data",OFFSET('Raw Data'!$N$4,A5-2,0)) -> 21.6
A6: 4 | B6: ='Raw Data'!N7 -> 33.4 | C6: =HLOOKUP("PRICE",'Raw Data'!$A$2:$N$3,2,FALSE) -> Price ($000s) | D6: {=INDIRECT("'Raw Data'!N"&(A6+3))} -> 33.4 | E6: =IF(A6=506,"End Of Data",OFFSET('Raw Data'!$N$4,A6,0)) -> 36.2 | F6: =IF(A6=1,"Start of Data",OFFSET('Raw Data'!$N$4,A6-2,0)) -> 34.7
A7: 5 | B7: ='Raw Data'!N8 -> 36.2 | C7: =HLOOKUP("PRICE",'Raw Data'!$A$2:$N$3,2,FALSE) -> Price ($000s) | D7: {=INDIRECT("'Raw Data'!N"&(A7+3))} -> 36.2 | E7: =IF(A7=506,"End Of Data",OFFSET('Raw Data'!$N$4,A7,0)) -> 28.7 | F7: =IF(A7=1,"Start of Data",OFFSET('Raw Data'!$N$4,A7-2,0)) -> 33.4
A8: 6 | B8: ='Raw Data'!N9 -> 28.7 | C8: =HLOOKUP("PRICE",'Raw Data'!$A$2:$N$3,2,FALSE) -> Price ($000s) | D8: {=INDIRECT("'Raw Data'!N"&(A8+3))} -> 28.7 | E8: =IF(A8=506,"End Of Data",OFFSET('Raw Data'!$N$4,A8,0)) -> 22.9 | F8: =IF(A8=1,"Start of Data",OFFSET('Raw Data'!$N$4,A8-2,0)) -> 36.2
A9: 7 | B9: ='Raw Data'!N10 -> 22.9 | C9: =HLOOKUP("PRICE",'Raw Data'!$A$2:$N$3,2,FALSE) -> Price ($000s) | D9: {=INDIRECT("'Raw Data'!N"&(A9+3))} -> 22.9 | E9: =IF(A9=506,"End Of Data",OFFSET('Raw Data'!$N$4,A9,0)) -> 27.1 | F9: =IF(A9=1,"Start of Data",OFFSET('Raw Data'!$N$4,A9-2,0)) -> 28.7
A10: 8 | B10: ='Raw Data'!N11 -> 27.1 | C10: =HLOOKUP("PRICE",'Raw Data'!$A$2:$N$3,2,FALSE) -> Price ($000s) | D10: {=INDIRECT("'Raw Data'!N"&(A10+3))} -> 27.1 | E10: =IF(A10=506,"End Of Data",OFFSET('Raw Data'!$N$4,A10,0)) -> 16.5 | F10: =IF(A10=1,"Start of Data",OFFSET('Raw Data'!$N$4,A10-2,0)) -> 22.9
A11: 9 | B11: ='Raw Data'!N12 -> 16.5 | C11: =HLOOKUP("PRICE",'Raw Data'!$A$2:$N$3,2,FALSE) -> Price ($000s) | D11: {=INDIRECT("'Raw Data'!N"&(A11+3))} -> 16.5 | E11: =IF(A11=506,"End Of Data",OFFSET('Raw Data'!$N$4,A11,0)) -> 18.9 | F11: =IF(A11=1,"Start of Data",OFFSET('Raw Data'!$N$4,A11-2,0)) -> 27.1
A12: 10 | B12: ='Raw Data'!N13 -> 18.9 | C12: =HLOOKUP("PRICE",'Raw Data'!$A$2:$N$3,2,FALSE) -> Price ($000s) | D12: {=INDIRECT("'Raw Data'!N"&(A12+3))} -> 18.9 | E12: =IF(A12=506,"End Of Data",OFFSET('Raw Data'!$N$4,A12,0)) -> 15 | F12: =IF(A12=1,"Start of Data",OFFSET('Raw Data'!$N$4,A12-2,0)) -> 16.5
A13: 11 | B13: ='Raw Data'!N14 -> 15 | C13: =HLOOKUP("PRICE",'Raw Data'!$A$2:$N$3,2,FALSE) -> Price ($000s) | D13: {=INDIRECT("'Raw Data'!N"&(A13+3))} -> 15 | E13: =IF(A13=506,"End Of Data",OFFSET('Raw Data'!$N$4,A13,0)) -> 18.9 | F13: =IF(A13=1,"Start of Data",OFFSET('Raw Data'!$N$4,A13-2,0)) -> 18.9
A14: 12 | B14: ='Raw Data'!N15 -> 18.9 | C14: =HLOOKUP("PRICE",'Raw Data'!$A$2:$N$3,2,FALSE) -> Price ($000s) | D14: {=INDIRECT("'Raw Data'!N"&(A14+3))} -> 18.9 | E14: =IF(A14=506,"End Of Data",OFFSET('Raw Data'!$N$4,A14,0)) -> 21.7 | F14: =IF(A14=1,"Start of Data",OFFSET('Raw Data'!$N$4,A14-2,0)) -> 15
... A508: 506 | B508: ='Raw Data'!N509 -> 11.9 | C508: =HLOOKUP("PRICE",'Raw Data'!$A$2:$N$3,2,FALSE) -> Price ($000s) | D508: {=INDIRECT("'Raw Data'!N"&(A508+3))} -> 11.9 | E508: =IF(A508=506,"End Of Data",OFFSET('Raw Data'!$N$4,A508,0)) -> End Of Data | F508: =IF(A508=1,"Start of Data",OFFSET('Raw Data'!$N$4,A508-2,0)) -> 22

Sheet Sheet1

Sheet Summary & Documentation
A1: Task 1 Summary - All Logical & Conditional Functions Applied
A2: FUNCTION | B2: FORMULA USED | C2: BUSINESS PURPOSE
A3: IF | B3: '=IF(price<=15,"Low",IF(price<=25,"Medium","High")) | C3: Categorises prices into 3 tiers: Low / Medium / High
A4: Nested IF (IFS) | B4: '=IF(p<=10,"Very Low",IF(p<=20,"Low",IF(p<=30,"Medium",...))) | C4: 5-tier classification (Very Low to Very High)
A5: AND | B5: '=IF(AND(price<=22,rooms>=6),"Affordable & Spacious","No") | C5: Flags houses meeting BOTH affordability AND space criteria
A6: OR | B6: '=IF(OR(chas=1,crimerate<0.1),"Desirable","No") | C6: Marks houses near river OR in low-crime areas
A7: NOT | B7: '=IF(NOT(crimerate>=1),"Safe Area","High Crime") | C7: Inverts high-crime flag to identify safe areas
A8: Nested IF (Investment) | B8: '=IF(p>=35,IF(crime<0.5,"Grade A","Grade B"),...) | C8: Grades houses A-D based on price and crime combination
A9: CHOOSE | B9: '=CHOOSE(MIN(5,MAX(1,INT(rad/5)+1)),"Very Low",...,"Very High") | C9: Converts numeric highway index into readable category
A10: IF (Price Band) | B10: '=IF(p<15,"Under 15k",IF(p<25,"15-25k",...)) | C10: Maps price to labelled band (SWITCH equivalent)
A11: ISNUMBER | B11: '=IF(ISNUMBER(price),"Valid Number","Not a Number") | C11: Validates that price column contains numeric data
A12: ISBLANK | B12: '=IF(ISBLANK(price),"Missing","Data Present") | C12: Detects empty/missing cells in the dataset
A13: IFERROR | B13: '=IFERROR(price/crimerate,"Error: Div by Zero") | C13: Prevents crash when dividing by zero crime rate
A15: Dataset: Boston House Prediction | 506 rows × 14 columns | Codveda Advanced Excel Internship — Level 1, Task 1
A18: Task 2 Summary - Advanced Lookup & Reference Functions
A19: FUNCTION | B19: FORMULA USED | C19: BUSINESS PURPOSE
A20: VLOOKUP | B20: =VLOOKUP(CrimeRate,'Raw Data'!A$4:N$508,14,FALSE) | C20: Looks up crime rate and returns corresponding house price
A21: XLOOKUP | B21: =XLOOKUP(Price,N$4:N509,A4:A$508,"Not Found" | C21: Searches price column and returns crime rate -------cleaner than VLOOKUP
A22: INDEX-MATCH (MAX) | B22: =INDEX(A$4:A508,MATCH(MAX(N4:N509),N4:N$509,0)) | C22: Finds crime rate of the most expensive house in dataset
A23: INDEX-MATCH (MIN) | B23: =INDEX(F$4:F509,MATCH(MIN(N4:N509),N4:N$509,0)) | C23: Finds average rooms of the cheapest house in dataset
A24: HLOOKUP | B24: =HLOOKUP(ColNumber,'Raw Data'!A$2:N$3,2,FALSE) | C24: Searches across header row and returns column description
A25: INDIRECT | B25: =INDIRECT("'Raw Data'!N"&(A3+3) | C25: Builds cell adress dynamically as text and fetches its value.
A26: OFFSET (Next) | B26: =IF(A3=506,"End of Data",OFFSET($N$4,A3,0)) | C26: Returns price of next house ---- shows End of Data at last row.
A27: OFFSET (Previous) | B27: =IF(A3=1,"Start of Data",OFFSET($N$4,A3-2,0)) | C27: Returns price of previous house ----- shows start of Data at first row
A29: Dataset: Boston House Prediction | 506 rows × 14 columns | Codveda Advanced Excel Internship — Level 1, Task 2
