Workbook
Name NativeTimeline_Timestamp: #N/A
Name Slicer_Country__Cleaned: #N/A
Name Slicer_Platform__Cleaned: #N/A
Name Slicer_Sentiment__Cleaned: #N/A

Sheet Raw Data
A1: Social Media Sentiment Dataset - Raw Data
A2: ID | B2: Post Text | C2: Sentiment | D2: Timestamp | E2: Username | F2: Platform | G2: Hashtags | H2: Retweets | I2: Likes | J2: Country | K2: Year | L2: Month | M2: Day | N2: Hour
A3: 0 | B3: Enjoying a beautiful day at the park! | C3: Positive | D3: 44941.521 | E3: User123 | F3: Twitter | G3: #Nature #Park | H3: 15 | I3: 30 | J3: USA | K3: 2023 | L3: 1 | M3: 15 | N3: 12
A4: 1 | B4: Traffic was terrible this morning. | C4: Negative | D4: 44941.365 | E4: CommuterX | F4: Twitter | G4: #Traffic #Morning | H4: 5 | I4: 10 | J4: Canada | K4: 2023 | L4: 1 | M4: 15 | N4: 8
A5: 2 | B5: Just finished an amazing workout! 💪 | C5: Positive | D5: 44941.656 | E5: FitnessFan | F5: Instagram | G5: #Fitness #Workout | H5: 20 | I5: 40 | J5: USA | K5: 2023 | L5: 1 | M5: 15 | N5: 15
A6: 3 | B6: Excited about the upcoming weekend getaway! | C6: Positive | D6: 44941.764 | E6: AdventureX | F6: Facebook | G6: #Travel #Adventure | H6: 8 | I6: 15 | J6: UK | K6: 2023 | L6: 1 | M6: 15 | N6: 18
A7: 4 | B7: Trying out a new recipe for dinner tonight. | C7: Neutral | D7: 44941.83 | E7: ChefCook | F7: Instagram | G7: #Cooking #Food | H7: 12 | I7: 25 | J7: Australia | K7: 2023 | L7: 1 | M7: 15 | N7: 19
A8: 5 | B8: Feeling grateful for the little things in life. | C8: Positive | D8: 44942.382 | E8: GratitudeNow | F8: Twitter | G8: #Gratitude #PositiveVibes | H8: 25 | I8: 50 | J8: India | K8: 2023 | L8: 1 | M8: 16 | N8: 9
A9: 6 | B9: Rainy days call for cozy blankets and hot cocoa. | C9: Positive | D9: 44942.615 | E9: RainyDays | F9: Facebook | G9: #RainyDays #Cozy | H9: 10 | I9: 20 | J9: Canada | K9: 2023 | L9: 1 | M9: 16 | N9: 14
A10: 7 | B10: The new movie release is a must-watch! | C10: Positive | D10: 44942.812 | E10: MovieBuff | F10: Instagram | G10: #MovieNight #MustWatch | H10: 15 | I10: 30 | J10: USA | K10: 2023 | L10: 1 | M10: 16 | N10: 19
A11: 8 | B11: Political discussions heating up on the timeline. | C11: Negative | D11: 44943.333 | E11: DebateTalk | F11: Twitter | G11: #Politics #Debate | H11: 30 | I11: 60 | J11: USA | K11: 2023 | L11: 1 | M11: 17 | N11: 8
A12: 9 | B12: Missing summer vibes and beach days. | C12: Neutral | D12: 44943.514 | E12: BeachLover | F12: Facebook | G12: #Summer #BeachDays | H12: 18 | I12: 35 | J12: Australia | K12: 2023 | L12: 1 | M12: 17 | N12: 12
A13: 10 | B13: Just published a new blog post. Check it out! | C13: Positive | D13: 44943.635 | E13: BloggerX | F13: Instagram | G13: #Blogging #NewPost | H13: 22 | I13: 45 | J13: USA | K13: 2023 | L13: 1 | M13: 17 | N13: 15
A14: 11 | B14: Feeling a bit under the weather today. | C14: Negative | D14: 44944.438 | E14: WellnessCheck | F14: Twitter | G14: #SickDay #Health | H14: 7 | I14: 15 | J14: Canada | K14: 2023 | L14: 1 | M14: 18 | N14: 10
... A734: 732 | B734: Organizing a virtual talent show during challenging times, bringing smiles to classmates' faces! | C734: Happy | D734: 44150.635 | E734: VirtualTalentShowSuccessHighSchool | F734: Instagram | G734: #VirtualEntertainment #HighSchoolPositivity | H734: 24 | I734: 47 | J734: USA | K734: 2020 | L734: 11 | M734: 15 | N734: 15

Sheet L2 T1 - Cleaned Data
A1: Social Media Sentiment Dataset
A2: ID | B2: Post Text (Cleaned) | C2: Sentiment (Cleaned) | D2: Timestamp | E2: Username (Cleaned) | F2: Platform (Cleaned) | G2: Hashtags (Cleaned) | H2: Retweets | I2: Likes | J2: Country (Cleaned) | K2: Year | L2: Month | M2: Day | N2: Hour
A3: ='Raw Data'!A3 -> 0 | B3: =TRIM(CLEAN('Raw Data'!B3)) -> Enjoying a beautiful day at the park! | C3: =TRIM(PROPER('Raw Data'!C3)) -> Positive | D3: ='Raw Data'!D3 -> 44941.521 | E3: =TRIM(SUBSTITUTE('Raw Data'!E3," "," ")) -> User123 | F3: =TRIM(PROPER('Raw Data'!F3)) -> Twitter | G3: =TRIM(CLEAN('Raw Data'!G3)) -> #Nature #Park | H3: ='Raw Data'!H3 -> 15 | I3: ='Raw Data'!I3 -> 30 | J3: =TRIM(UPPER('Raw Data'!J3)) -> USA | K3: ='Raw Data'!K3 -> 2023 | L3: ='Raw Data'!L3 -> 1 | M3: ='Raw Data'!M3 -> 15 | N3: ='Raw Data'!N3 -> 12
A4: ='Raw Data'!A4 -> 1 | B4: =TRIM(CLEAN('Raw Data'!B4)) -> Traffic was terrible this morning. | C4: =TRIM(PROPER('Raw Data'!C4)) -> Negative | D4: ='Raw Data'!D4 -> 44941.365 | E4: =TRIM(SUBSTITUTE('Raw Data'!E4," "," ")) -> CommuterX | F4: =TRIM(PROPER('Raw Data'!F4)) -> Twitter | G4: =TRIM(CLEAN('Raw Data'!G4)) -> #Traffic #Morning | H4: ='Raw Data'!H4 -> 5 | I4: 30 | J4: =TRIM(UPPER('Raw Data'!J4)) -> CANADA | K4: ='Raw Data'!K4 -> 2023 | L4: ='Raw Data'!L4 -> 1 | M4: ='Raw Data'!M4 -> 15 | N4: ='Raw Data'!N4 -> 8
A5: ='Raw Data'!A5 -> 2 | B5: =TRIM(CLEAN('Raw Data'!B5)) -> Just finished an amazing workout! 💪 | C5: =TRIM(PROPER('Raw Data'!C5)) -> Positive | D5: ='Raw Data'!D5 -> 44941.656 | E5: =TRIM(SUBSTITUTE('Raw Data'!E5," "," ")) -> FitnessFan | F5: =TRIM(PROPER('Raw Data'!F5)) -> Instagram | G5: =TRIM(CLEAN('Raw Data'!G5)) -> #Fitness #Workout | H5: ='Raw Data'!H5 -> 20 | I5: 10 | J5: =TRIM(UPPER('Raw Data'!J5)) -> USA | K5: ='Raw Data'!K5 -> 2023 | L5: ='Raw Data'!L5 -> 1 | M5: ='Raw Data'!M5 -> 15 | N5: ='Raw Data'!N5 -> 15
A6: ='Raw Data'!A6 -> 3 | B6: =TRIM(CLEAN('Raw Data'!B6)) -> Excited about the upcoming weekend getaway! | C6: =TRIM(PROPER('Raw Data'!C6)) -> Positive | D6: ='Raw Data'!D6 -> 44941.764 | E6: =TRIM(SUBSTITUTE('Raw Data'!E6," "," ")) -> AdventureX | F6: =TRIM(PROPER('Raw Data'!F6)) -> Facebook | G6: =TRIM(CLEAN('Raw Data'!G6)) -> #Travel #Adventure | H6: ='Raw Data'!H6 -> 8 | I6: 40 | J6: =TRIM(UPPER('Raw Data'!J6)) -> UK | K6: ='Raw Data'!K6 -> 2023 | L6: ='Raw Data'!L6 -> 1 | M6: ='Raw Data'!M6 -> 15 | N6: ='Raw Data'!N6 -> 18
A7: ='Raw Data'!A7 -> 4 | B7: =TRIM(CLEAN('Raw Data'!B7)) -> Trying out a new recipe for dinner tonight. | C7: =TRIM(PROPER('Raw Data'!C7)) -> Neutral | D7: ='Raw Data'!D7 -> 44941.83 | E7: =TRIM(SUBSTITUTE('Raw Data'!E7," "," ")) -> ChefCook | F7: =TRIM(PROPER('Raw Data'!F7)) -> Instagram | G7: =TRIM(CLEAN('Raw Data'!G7)) -> #Cooking #Food | H7: ='Raw Data'!H7 -> 12 | I7: 15 | J7: =TRIM(UPPER('Raw Data'!J7)) -> AUSTRALIA | K7: ='Raw Data'!K7 -> 2023 | L7: ='Raw Data'!L7 -> 1 | M7: ='Raw Data'!M7 -> 15 | N7: ='Raw Data'!N7 -> 19
A8: ='Raw Data'!A8 -> 5 | B8: =TRIM(CLEAN('Raw Data'!B8)) -> Feeling grateful for the little things in life. | C8: =TRIM(PROPER('Raw Data'!C8)) -> Positive | D8: ='Raw Data'!D8 -> 44942.382 | E8: =TRIM(SUBSTITUTE('Raw Data'!E8," "," ")) -> GratitudeNow | F8: =TRIM(PROPER('Raw Data'!F8)) -> Twitter | G8: =TRIM(CLEAN('Raw Data'!G8)) -> #Gratitude #PositiveVibes | H8: ='Raw Data'!H8 -> 25 | I8: 25 | J8: =TRIM(UPPER('Raw Data'!J8)) -> INDIA | K8: ='Raw Data'!K8 -> 2023 | L8: ='Raw Data'!L8 -> 1 | M8: ='Raw Data'!M8 -> 16 | N8: ='Raw Data'!N8 -> 9
A9: ='Raw Data'!A9 -> 6 | B9: =TRIM(CLEAN('Raw Data'!B9)) -> Rainy days call for cozy blankets and hot cocoa. | C9: =TRIM(PROPER('Raw Data'!C9)) -> Positive | D9: ='Raw Data'!D9 -> 44942.615 | E9: =TRIM(SUBSTITUTE('Raw Data'!E9," "," ")) -> RainyDays | F9: =TRIM(PROPER('Raw Data'!F9)) -> Facebook | G9: =TRIM(CLEAN('Raw Data'!G9)) -> #RainyDays #Cozy | H9: ='Raw Data'!H9 -> 10 | I9: 50 | J9: =TRIM(UPPER('Raw Data'!J9)) -> CANADA | K9: ='Raw Data'!K9 -> 2023 | L9: ='Raw Data'!L9 -> 1 | M9: ='Raw Data'!M9 -> 16 | N9: ='Raw Data'!N9 -> 14
A10: ='Raw Data'!A10 -> 7 | B10: =TRIM(CLEAN('Raw Data'!B10)) -> The new movie release is a must-watch! | C10: =TRIM(PROPER('Raw Data'!C10)) -> Positive | D10: ='Raw Data'!D10 -> 44942.812 | E10: =TRIM(SUBSTITUTE('Raw Data'!E10," "," ")) -> MovieBuff | F10: =TRIM(PROPER('Raw Data'!F10)) -> Instagram | G10: =TRIM(CLEAN('Raw Data'!G10)) -> #MovieNight #MustWatch | H10: ='Raw Data'!H10 -> 15 | I10: 20 | J10: =TRIM(UPPER('Raw Data'!J10)) -> USA | K10: ='Raw Data'!K10 -> 2023 | L10: ='Raw Data'!L10 -> 1 | M10: ='Raw Data'!M10 -> 16 | N10: ='Raw Data'!N10 -> 19
A11: ='Raw Data'!A11 -> 8 | B11: =TRIM(CLEAN('Raw Data'!B11)) -> Political discussions heating up on the timeline. | C11: =TRIM(PROPER('Raw Data'!C11)) -> Negative | D11: ='Raw Data'!D11 -> 44943.333 | E11: =TRIM(SUBSTITUTE('Raw Data'!E11," "," ")) -> DebateTalk | F11: =TRIM(PROPER('Raw Data'!F11)) -> Twitter | G11: =TRIM(CLEAN('Raw Data'!G11)) -> #Politics #Debate | H11: ='Raw Data'!H11 -> 30 | I11: 30 | J11: =TRIM(UPPER('Raw Data'!J11)) -> USA | K11: ='Raw Data'!K11 -> 2023 | L11: ='Raw Data'!L11 -> 1 | M11: ='Raw Data'!M11 -> 17 | N11: ='Raw Data'!N11 -> 8
A12: ='Raw Data'!A12 -> 9 | B12: =TRIM(CLEAN('Raw Data'!B12)) -> Missing summer vibes and beach days. | C12: =TRIM(PROPER('Raw Data'!C12)) -> Neutral | D12: ='Raw Data'!D12 -> 44943.514 | E12: =TRIM(SUBSTITUTE('Raw Data'!E12," "," ")) -> BeachLover | F12: =TRIM(PROPER('Raw Data'!F12)) -> Facebook | G12: =TRIM(CLEAN('Raw Data'!G12)) -> #Summer #BeachDays | H12: ='Raw Data'!H12 -> 18 | I12: 60 | J12: =TRIM(UPPER('Raw Data'!J12)) -> AUSTRALIA | K12: ='Raw Data'!K12 -> 2023 | L12: ='Raw Data'!L12 -> 1 | M12: ='Raw Data'!M12 -> 17 | N12: ='Raw Data'!N12 -> 12
A13: ='Raw Data'!A13 -> 10 | B13: =TRIM(CLEAN('Raw Data'!B13)) -> Just published a new blog post. Check it out! | C13: =TRIM(PROPER('Raw Data'!C13)) -> Positive | D13: ='Raw Data'!D13 -> 44943.635 | E13: =TRIM(SUBSTITUTE('Raw Data'!E13," "," ")) -> BloggerX | F13: =TRIM(PROPER('Raw Data'!F13)) -> Instagram | G13: =TRIM(CLEAN('Raw Data'!G13)) -> #Blogging #NewPost | H13: ='Raw Data'!H13 -> 22 | I13: 35 | J13: =TRIM(UPPER('Raw Data'!J13)) -> USA | K13: ='Raw Data'!K13 -> 2023 | L13: ='Raw Data'!L13 -> 1 | M13: ='Raw Data'!M13 -> 17 | N13: ='Raw Data'!N13 -> 15
A14: ='Raw Data'!A14 -> 11 | B14: =TRIM(CLEAN('Raw Data'!B14)) -> Feeling a bit under the weather today. | C14: =TRIM(PROPER('Raw Data'!C14)) -> Negative | D14: ='Raw Data'!D14 -> 44944.438 | E14: =TRIM(SUBSTITUTE('Raw Data'!E14," "," ")) -> WellnessCheck | F14: =TRIM(PROPER('Raw Data'!F14)) -> Twitter | G14: =TRIM(CLEAN('Raw Data'!G14)) -> #SickDay #Health | H14: ='Raw Data'!H14 -> 7 | I14: 45 | J14: =TRIM(UPPER('Raw Data'!J14)) -> CANADA | K14: ='Raw Data'!K14 -> 2023 | L14: ='Raw Data'!L14 -> 1 | M14: ='Raw Data'!M14 -> 18 | N14: ='Raw Data'!N14 -> 10
A15: ='Raw Data'!A15 -> 12 | B15: =TRIM(CLEAN('Raw Data'!B15)) -> Exploring the city's hidden gems. | C15: =TRIM(PROPER('Raw Data'!C15)) -> Positive | D15: ='Raw Data'!D15 -> 44944.618 | E15: =TRIM(SUBSTITUTE('Raw Data'!E15," "," ")) -> UrbanExplorer | F15: =TRIM(PROPER('Raw Data'!F15)) -> Facebook | G15: =TRIM(CLEAN('Raw Data'!G15)) -> #CityExplore #HiddenGems | H15: ='Raw Data'!H15 -> 12 | I15: 15 | J15: =TRIM(UPPER('Raw Data'!J15)) -> UK | K15: ='Raw Data'!K15 -> 2023 | L15: ='Raw Data'!L15 -> 1 | M15: ='Raw Data'!M15 -> 18 | N15: ='Raw Data'!N15 -> 14
... A734: ='Raw Data'!A734 -> 732 | B734: =TRIM(CLEAN('Raw Data'!B734)) -> Organizing a virtual talent show during challenging times, bringing smiles to classmates' faces! | C734: =TRIM(PROPER('Raw Data'!C734)) -> Happy | D734: ='Raw Data'!D734 -> 44150.635 | E734: =TRIM(SUBSTITUTE('Raw Data'!E734," "," ")) -> VirtualTalentShowSuccessHighSchool | F734: =TRIM(PROPER('Raw Data'!F734)) -> Instagram | G734: =TRIM(CLEAN('Raw Data'!G734)) -> #VirtualEntertainment #HighSchoolPositivity | H734: ='Raw Data'!H734 -> 24 | I734: 43 | J734: =TRIM(UPPER('Raw Data'!J734)) -> USA | K734: ='Raw Data'!K734 -> 2020 | L734: ='Raw Data'!L734 -> 11 | M734: ='Raw Data'!M734 -> 15 | N734: ='Raw Data'!N734 -> 15

Sheet L2 T1 - Text Functions
A1: Task 1: Text Cleaning Functions - TRIM, CLEAN, SUBSTITUTE, UPPER, LOWER, PROPER, LEN
A2: Row# | B2: Original Value | C2: TRIM: Remove Spaces | D2: CLEAN: Remove Characters | E2: SUBSTITUTE: Replace Text | F2: UPPER: All Caps | G2: LOWER: All Lowercase | H2: PROPER: Title Case | I2: LEN: Original Length | J2: LEN: After TRIM Length | K2: Difference
A3: ='Raw Data'!A3 -> 0 | B3: ='Raw Data'!C3 -> Positive | C3: =TRIM(B3) -> Positive | D3: =CLEAN(B3) -> Positive | E3: =SUBSTITUTE(SUBSTITUTE(SUBSTITUTE(TRIM(B3),"Positive","Pos"),"Negative","Neg"),"Neutral","Neu") -> Pos | F3: =UPPER(TRIM(B3)) -> POSITIVE | G3: =LOWER(TRIM(B3)) -> positive | H3: =PROPER(TRIM(B3)) -> Positive | I3: =LEN(B3) -> 11 | J3: =LEN(TRIM(B3)) -> 8 | K3: =I3-J3 -> 3
A4: ='Raw Data'!A4 -> 1 | B4: ='Raw Data'!C4 -> Negative | C4: =TRIM(B4) -> Negative | D4: =CLEAN(B4) -> Negative | E4: =SUBSTITUTE(SUBSTITUTE(SUBSTITUTE(TRIM(B4),"Positive","Pos"),"Negative","Neg"),"Neutral","Neu") -> Neg | F4: =UPPER(TRIM(B4)) -> NEGATIVE | G4: =LOWER(TRIM(B4)) -> negative | H4: =PROPER(TRIM(B4)) -> Negative | I4: =LEN(B4) -> 11 | J4: =LEN(TRIM(B4)) -> 8 | K4: =I4-J4 -> 3
A5: ='Raw Data'!A5 -> 2 | B5: ='Raw Data'!C5 -> Positive | C5: =TRIM(B5) -> Positive | D5: =CLEAN(B5) -> Positive | E5: =SUBSTITUTE(SUBSTITUTE(SUBSTITUTE(TRIM(B5),"Positive","Pos"),"Negative","Neg"),"Neutral","Neu") -> Pos | F5: =UPPER(TRIM(B5)) -> POSITIVE | G5: =LOWER(TRIM(B5)) -> positive | H5: =PROPER(TRIM(B5)) -> Positive | I5: =LEN(B5) -> 11 | J5: =LEN(TRIM(B5)) -> 8 | K5: =I5-J5 -> 3
A6: ='Raw Data'!A6 -> 3 | B6: ='Raw Data'!C6 -> Positive | C6: =TRIM(B6) -> Positive | D6: =CLEAN(B6) -> Positive | E6: =SUBSTITUTE(SUBSTITUTE(SUBSTITUTE(TRIM(B6),"Positive","Pos"),"Negative","Neg"),"Neutral","Neu") -> Pos | F6: =UPPER(TRIM(B6)) -> POSITIVE | G6: =LOWER(TRIM(B6)) -> positive | H6: =PROPER(TRIM(B6)) -> Positive | I6: =LEN(B6) -> 11 | J6: =LEN(TRIM(B6)) -> 8 | K6: =I6-J6 -> 3
A7: ='Raw Data'!A7 -> 4 | B7: ='Raw Data'!C7 -> Neutral | C7: =TRIM(B7) -> Neutral | D7: =CLEAN(B7) -> Neutral | E7: =SUBSTITUTE(SUBSTITUTE(SUBSTITUTE(TRIM(B7),"Positive","Pos"),"Negative","Neg"),"Neutral","Neu") -> Neu | F7: =UPPER(TRIM(B7)) -> NEUTRAL | G7: =LOWER(TRIM(B7)) -> neutral | H7: =PROPER(TRIM(B7)) -> Neutral | I7: =LEN(B7) -> 11 | J7: =LEN(TRIM(B7)) -> 7 | K7: =I7-J7 -> 4
A8: ='Raw Data'!A8 -> 5 | B8: ='Raw Data'!C8 -> Positive | C8: =TRIM(B8) -> Positive | D8: =CLEAN(B8) -> Positive | E8: =SUBSTITUTE(SUBSTITUTE(SUBSTITUTE(TRIM(B8),"Positive","Pos"),"Negative","Neg"),"Neutral","Neu") -> Pos | F8: =UPPER(TRIM(B8)) -> POSITIVE | G8: =LOWER(TRIM(B8)) -> positive | H8: =PROPER(TRIM(B8)) -> Positive | I8: =LEN(B8) -> 11 | J8: =LEN(TRIM(B8)) -> 8 | K8: =I8-J8 -> 3
A9: ='Raw Data'!A9 -> 6 | B9: ='Raw Data'!C9 -> Positive | C9: =TRIM(B9) -> Positive | D9: =CLEAN(B9) -> Positive | E9: =SUBSTITUTE(SUBSTITUTE(SUBSTITUTE(TRIM(B9),"Positive","Pos"),"Negative","Neg"),"Neutral","Neu") -> Pos | F9: =UPPER(TRIM(B9)) -> POSITIVE | G9: =LOWER(TRIM(B9)) -> positive | H9: =PROPER(TRIM(B9)) -> Positive | I9: =LEN(B9) -> 11 | J9: =LEN(TRIM(B9)) -> 8 | K9: =I9-J9 -> 3
A10: ='Raw Data'!A10 -> 7 | B10: ='Raw Data'!C10 -> Positive | C10: =TRIM(B10) -> Positive | D10: =CLEAN(B10) -> Positive | E10: =SUBSTITUTE(SUBSTITUTE(SUBSTITUTE(TRIM(B10),"Positive","Pos"),"Negative","Neg"),"Neutral","Neu") -> Pos | F10: =UPPER(TRIM(B10)) -> POSITIVE | G10: =LOWER(TRIM(B10)) -> positive | H10: =PROPER(TRIM(B10)) -> Positive | I10: =LEN(B10) -> 11 | J10: =LEN(TRIM(B10)) -> 8 | K10: =I10-J10 -> 3
A11: ='Raw Data'!A11 -> 8 | B11: ='Raw Data'!C11 -> Negative | C11: =TRIM(B11) -> Negative | D11: =CLEAN(B11) -> Negative | E11: =SUBSTITUTE(SUBSTITUTE(SUBSTITUTE(TRIM(B11),"Positive","Pos"),"Negative","Neg"),"Neutral","Neu") -> Neg | F11: =UPPER(TRIM(B11)) -> NEGATIVE | G11: =LOWER(TRIM(B11)) -> negative | H11: =PROPER(TRIM(B11)) -> Negative | I11: =LEN(B11) -> 11 | J11: =LEN(TRIM(B11)) -> 8 | K11: =I11-J11 -> 3
A12: ='Raw Data'!A12 -> 9 | B12: ='Raw Data'!C12 -> Neutral | C12: =TRIM(B12) -> Neutral | D12: =CLEAN(B12) -> Neutral | E12: =SUBSTITUTE(SUBSTITUTE(SUBSTITUTE(TRIM(B12),"Positive","Pos"),"Negative","Neg"),"Neutral","Neu") -> Neu | F12: =UPPER(TRIM(B12)) -> NEUTRAL | G12: =LOWER(TRIM(B12)) -> neutral | H12: =PROPER(TRIM(B12)) -> Neutral | I12: =LEN(B12) -> 11 | J12: =LEN(TRIM(B12)) -> 7 | K12: =I12-J12 -> 4
A13: ='Raw Data'!A13 -> 10 | B13: ='Raw Data'!C13 -> Positive | C13: =TRIM(B13) -> Positive | D13: =CLEAN(B13) -> Positive | E13: =SUBSTITUTE(SUBSTITUTE(SUBSTITUTE(TRIM(B13),"Positive","Pos"),"Negative","Neg"),"Neutral","Neu") -> Pos | F13: =UPPER(TRIM(B13)) -> POSITIVE | G13: =LOWER(TRIM(B13)) -> positive | H13: =PROPER(TRIM(B13)) -> Positive | I13: =LEN(B13) -> 11 | J13: =LEN(TRIM(B13)) -> 8 | K13: =I13-J13 -> 3
A14: ='Raw Data'!A14 -> 11 | B14: ='Raw Data'!C14 -> Negative | C14: =TRIM(B14) -> Negative | D14: =CLEAN(B14) -> Negative | E14: =SUBSTITUTE(SUBSTITUTE(SUBSTITUTE(TRIM(B14),"Positive","Pos"),"Negative","Neg"),"Neutral","Neu") -> Neg | F14: =UPPER(TRIM(B14)) -> NEGATIVE | G14: =LOWER(TRIM(B14)) -> negative | H14: =PROPER(TRIM(B14)) -> Negative | I14: =LEN(B14) -> 11 | J14: =LEN(TRIM(B14)) -> 8 | K14: =I14-J14 -> 3
... A734: ='Raw Data'!A734 -> 732 | B734: ='Raw Data'!C734 -> Happy | C734: =TRIM(B734) -> Happy | D734: =CLEAN(B734) -> Happy | E734: =SUBSTITUTE(SUBSTITUTE(SUBSTITUTE(TRIM(B734),"Positive","Pos"),"Negative","Neg"),"Neutral","Neu") -> Happy | F734: =UPPER(TRIM(B734)) -> HAPPY | G734: =LOWER(TRIM(B734)) -> happy | H734: =PROPER(TRIM(B734)) -> Happy | I734: =LEN(B734) -> 7 | J734: =LEN(TRIM(B734)) -> 5 | K734: =I734-J734 -> 2

Sheet L2 T1 - Flash Fill
A1: Tak 1: Flash Fill & Find and Replace - Pattern Detection & Mass Updates
A2: Row# | B2: Original Timestamp | C2: Flash Fill: Year Extracted | D2: Flash Fill: Month Extracted | E2: Flash Fill: Date Only | F2: Flash Fill: Time Only | H2: Row# | I2: Original Country | J2: After Find & Replace | K2: Note
A3: ='Raw Data'!A3 -> 0 | B3: ='Raw Data'!D3 -> 44941.521 | C3: 2023 | D3: =TEXT(B3,"MMMM") -> January | E3: 15 | F3: 0.52083333 | H3: ='Raw Data'!A3 -> 0 | I3: ='Raw Data'!J3 -> USA | J3: United States | K3: =IF(I3=J3,"No Change","Updated") -> Updated
A4: ='Raw Data'!A4 -> 1 | B4: ='Raw Data'!D4 -> 44941.365 | C4: 2023 | D4: =TEXT(B4,"MMMM") -> January | E4: 15 | F4: 0.36458333 | H4: ='Raw Data'!A4 -> 1 | I4: ='Raw Data'!J4 -> Canada | J4: Canada | K4: =IF(I4=J4,"No Change","Updated") -> No Change
A5: ='Raw Data'!A5 -> 2 | B5: ='Raw Data'!D5 -> 44941.656 | C5: 2023 | D5: =TEXT(B5,"MMMM") -> January | E5: 15 | F5: 0.65625 | H5: ='Raw Data'!A5 -> 2 | I5: ='Raw Data'!J5 -> USA | J5: United States | K5: =IF(I5=J5,"No Change","Updated") -> Updated
A6: ='Raw Data'!A6 -> 3 | B6: ='Raw Data'!D6 -> 44941.764 | C6: 2023 | D6: =TEXT(B6,"MMMM") -> January | E6: 15 | F6: 0.76388889 | H6: ='Raw Data'!A6 -> 3 | I6: ='Raw Data'!J6 -> UK | J6: United Kingdom | K6: =IF(I6=J6,"No Change","Updated") -> Updated
A7: ='Raw Data'!A7 -> 4 | B7: ='Raw Data'!D7 -> 44941.83 | C7: 2023 | D7: =TEXT(B7,"MMMM") -> January | E7: 15 | F7: 0.82986111 | H7: ='Raw Data'!A7 -> 4 | I7: ='Raw Data'!J7 -> Australia | J7: Australia | K7: =IF(I7=J7,"No Change","Updated") -> No Change
A8: ='Raw Data'!A8 -> 5 | B8: ='Raw Data'!D8 -> 44942.382 | C8: 2023 | D8: =TEXT(B8,"MMMM") -> January | E8: 16 | F8: 0.38194444 | H8: ='Raw Data'!A8 -> 5 | I8: ='Raw Data'!J8 -> India | J8: India | K8: =IF(I8=J8,"No Change","Updated") -> No Change
A9: ='Raw Data'!A9 -> 6 | B9: ='Raw Data'!D9 -> 44942.615 | C9: 2023 | D9: =TEXT(B9,"MMMM") -> January | E9: 16 | F9: 0.61458333 | H9: ='Raw Data'!A9 -> 6 | I9: ='Raw Data'!J9 -> Canada | J9: Canada | K9: =IF(I9=J9,"No Change","Updated") -> No Change
A10: ='Raw Data'!A10 -> 7 | B10: ='Raw Data'!D10 -> 44942.812 | C10: 2023 | D10: =TEXT(B10,"MMMM") -> January | E10: 16 | F10: 0.8125 | H10: ='Raw Data'!A10 -> 7 | I10: ='Raw Data'!J10 -> USA | J10: United States | K10: =IF(I10=J10,"No Change","Updated") -> Updated
A11: ='Raw Data'!A11 -> 8 | B11: ='Raw Data'!D11 -> 44943.333 | C11: 2023 | D11: =TEXT(B11,"MMMM") -> January | E11: 17 | F11: 0.33333333 | H11: ='Raw Data'!A11 -> 8 | I11: ='Raw Data'!J11 -> USA | J11: United States | K11: =IF(I11=J11,"No Change","Updated") -> Updated
A12: ='Raw Data'!A12 -> 9 | B12: ='Raw Data'!D12 -> 44943.514 | C12: 2023 | D12: =TEXT(B12,"MMMM") -> January | E12: 17 | F12: 0.51388889 | H12: ='Raw Data'!A12 -> 9 | I12: ='Raw Data'!J12 -> Australia | J12: Australia | K12: =IF(I12=J12,"No Change","Updated") -> No Change
A13: ='Raw Data'!A13 -> 10 | B13: ='Raw Data'!D13 -> 44943.635 | C13: 2023 | D13: =TEXT(B13,"MMMM") -> January | E13: 17 | F13: 0.63541667 | H13: ='Raw Data'!A13 -> 10 | I13: ='Raw Data'!J13 -> USA | J13: United States | K13: =IF(I13=J13,"No Change","Updated") -> Updated
A14: ='Raw Data'!A14 -> 11 | B14: ='Raw Data'!D14 -> 44944.438 | C14: 2023 | D14: =TEXT(B14,"MMMM") -> January | E14: 18 | F14: 0.4375 | H14: ='Raw Data'!A14 -> 11 | I14: ='Raw Data'!J14 -> Canada | J14: Canada | K14: =IF(I14=J14,"No Change","Updated") -> No Change
... A734: ='Raw Data'!A734 -> 732 | B734: ='Raw Data'!D734 -> 44150.635 | C734: 2020 | D734: =TEXT(B734,"MMMM") -> November | E734: 15 | F734: 0.63541667 | H734: ='Raw Data'!A734 -> 732 | I734: ='Raw Data'!J734 -> USA | J734: United States | K734: =IF(I734=J734,"No Change","Updated") -> Updated

Sheet Summary
A1: Level 2 Task 1 Summary - Data Cleaning & Preprocessing
A2: Tool/Function | B2: How It Was Used | C2: Business Purpose
A3: TRIM | B3: Removed leading, trailing and extra spaces from Sentiment, Username, Platform, Country and Hashtags columns | C3: Ensures consistent values - "Positive " and "Positive" are treated as the same
A4: CLEAN | B4: Removed invisible non-printable characters from Post Text and Hashtags columns | C4: Prevents hidden characters from causing errors in analysis and formulas
A5: SUBSTITUTE | B5: Replaced full sentiment labels with short codes - Positive -> Pos, Negative -> Neg, Neutral -> Neu | C5: Standardizes labels for faster analysis and consistent categorization.
A6: UPPER | B6: Converted Country column to uppercase - USA,UK,CANADA | C6: Ensures consistent casing across all country values regardless of original format
A7: LOWER | B7: Demonstrated converting text to all lowercase | C7: Useful for case-insensitive comparisions and standardizing text fields.
A8: PROPER | B8: Standardized Platform and Sentiment columns -Twitter, Positive | C8: Ensures first letter is capitalized consistently across all values
A9: LEN | B9: Measured character length before and after TRIM to prove cleaning worked | C9: The difference in length confirms exactly how many dirty characters were removed
A10: Flash Fill | B10: Extracted Year, Date and Time from Timestamp column automatically | C10: Splits combined date-time values into separate components without complex formulas
A11: Find & Replace | B11: Mass updated country names - USA -> United States, UK-> United Kingdom across 732 rows | C11: Fastest way to standardize hundreds of values simultaneously
A12: Remove Duplicates | B12: Checked dataset for duplicate rows using Data -> Remove Duplicates | C12: Ensures each social media post is counted only once in analysis
A13: Known Limitation | B13: Emoji removal is not natively supported in Excel - CLEAN does not handle Unicode emoji characters | C13: For complete emoji removal Python regex or Power Query is recommended
A15: Datset: Social Media Sentiment Dataset | 732 rows x 14 columns | Codveda Advanced Excel Internship - Level 2, Task 1 & 2
A17: Level 2 Task 2 Summary - Pivot Tables & Pivot Charts
A18: Tool/Function | B18: How It Was Used | C18: Business Purpose
A19: Pivot Table 1 | B19: Counted total posts grouped by Sentiment category | C19: Shows which emotions dominate social media conversations
A20: Pivot Table 2 | B20: Counted total posts grouped by Platform. | C20: Reveals which social media platform has the most activity
A21: Pivot Table 3 | B21: Calculated average Likes and Retweets grouped by Country | C21: Identifies which countries generate the most engagement
A22: Pivot Table 4 | B22: Cross-tabulated posts by Platform and Sentiment combined | C22: Shows sentiment patterns across different platforms simultaneously
A23: Calculated Field | B23: Created engagement Rate formula inside Pivot Table 3 | C23: Measures ration of likes to retweets as a custom metric
A24: Slicers | B24: Added Platform, Country and Sentiment slicers connected to all 4 Pivot Tables | C24: Enables one-click interactive filtering across all tables simultaneously
A25: Timeline | B25: Added interactive date timeline connected to Pivot Table 1 | C25: Allows filtering of posts by specific months or date ranges
A26: Pivot Chart 1 | B26: Created clustered bar chart fro Pivot Table 1 showing posts by sentiment | C26: Visual comparision of sentiment distribution across all categories.
A27: Pivot Chart 2 | B27: Created pie chart from Pivot Table 2 showing platform share % | C27: Shows proportional contribution of each platform to total posts
A28: Pivot Chart 3 | B28: Created line chart showing post volume by month | C28: Reveals posting trends and patterns over time.

Sheet L2 T1 - Pivot Tables
A1: Task 2 : Pivot Tables & Interactive Analysis - Social Media Sentiment Dataset
A3: Pivot Table 1 - Posts by Sentiment | G3: Pivot Table 2 - Posts via Platform | K3: Pivot Table - Total posts per Month
A4: Row Labels | B4: Count of Post Text (Cleaned) | G4: Row Labels | H4: Total Posts | K4: Row Labels | L4: Total Values
A5: Acceptance | B5: 8 | G5: Facebook | H5: 231 | K5: 1 | L5: 12320
A6: Accomplishment | B6: 3 | G6: Instagram | H6: 258 | K6: 2 | L6: 15458
A7: Admiration | B7: 4 | G7: Twitter | H7: 243 | K7: 3 | L7: 13009
A8: Adoration | B8: 2 | G8: Grand Total | H8: 732 | K8: 4 | L8: 17827
A9: Adrenaline | B9: 1 | K9: 5 | L9: 18950
A10: Adventure | B10: 3 | K10: 6 | L10: 32891
A11: Affection | B11: 2 | K11: 7 | L11: 26757
A12: Amazement | B12: 1 | K12: 8 | L12: 37234
A13: Ambivalence | B13: 6 | G13: Pivot Table 3 - Average Likes & Retweets by Country | K13: 9 | L13: 37962
A14: Amusement | B14: 3 | G14: Row Labels | H14: Average of Likes | I14: Average of Retweets | K14: 10 | L14: 24196
A15: Anger | B15: 2 | G15: AUSTRALIA | H15: 38.453333 | I15: 19.52 | K15: 11 | L15: 18042
A16: Anticipation | B16: 3 | D16: Pivot Slicers | G16: AUSTRIA | H16: 60 | I16: 22 | K16: 12 | L16: 13606
A17: Anxiety | B17: 2 | G17: BELGIUM | H17: 45 | I17: 35 | K17: Grand Total | L17: 268252
A18: Appreciation | B18: 1 | G18: BRAZIL | H18: 45 | I18: 26.352941
A19: Apprehensive | B19: 2 | G19: CAMBODIA | H19: 55 | I19: 20 | K19: Post Count | L19: Column Labels
A20: Arousal | B20: 4 | G20: CANADA | H20: 40.881481 | I20: 20.377778 | K20: Row Labels | L20: Acceptance | M20: Accomplishment | N20: Admiration | O20: Adoration | P20: Adrenaline | Q20: Adventure | R20: Affection | S20: Amazement | T20: Ambivalence | U20: Amusement | V20: Anger | W20: Anticipation | X20: Anxiety | Y20: Appreciation | Z20: Apprehensive | AA20: Arousal | AB20: Artisticburst | AC20: Awe | AD20: Bad | AE20: Betrayal | AF20: Bitter | AG20: Bitterness | AH20: Bittersweet | AI20: Blessed | AJ20: Boredom | AK20: Breakthrough | AL20: Calmness | AM20: Captivation | AN20: Celebration | AO20: Celestial Wonder | AP20: Challenge | AQ20: Charm | AR20: Colorful | AS20: Compassion | AT20: Compassionate | AU20: Confidence | AV20: Confident | AW20: Confusion | AX20: Connection | AY20: Contemplation | AZ20: Contentment | BA20: Coziness | BB20: Creative Inspiration | BC20: Creativity | BD20: Culinary Adventure | BE20: Culinaryodyssey | BF20: Curiosity | BG20: Darkness | BH20: Dazzle | BI20: Desolation | BJ20: Despair | BK20: Desperation | BL20: Determination | BM20: Devastated | BN20: Disappointed | BO20: Disappointment | BP20: Disgust | BQ20: Dismissive | BR20: Dreamchaser | BS20: Ecstasy | BT20: Elation | BU20: Elegance | BV20: Embarrassed | BW20: Emotion | BX20: Emotionalstorm | BY20: Empathetic | BZ20: Empowerment | CA20: Enchantment | CB20: Energy | CC20: Engagement | CD20: Enjoyment | CE20: Enthusiasm | CF20: Envious | CG20: Envisioning History | CH20: Envy | CI20: Euphoria | CJ20: Excitement | CK20: Exhaustion | CL20: Exploration | CM20: Fear | CN20: Fearful | CO20: Festivejoy | CP20: Freedom | CQ20: Free-Spirited | CR20: Friendship | CS20: Frustrated | CT20: Frustration | CU20: Fulfillment | CV20: Grandeur | CW20: Grateful | CX20: Gratitude | CY20: Grief | CZ20: Happiness | DA20: Happy | DB20: Harmony | DC20: Hate | DD20: Heartache | DE20: Heartbreak | DF20: Heartwarming | DG20: Helplessness | DH20: Hope | DI20: Hopeful | DJ20: Hypnotic | DK20: Iconic | DL20: Imagination | DM20: Immersion | DN20: Indifference | DO20: Innerjourney | DP20: Inspiration | DQ20: Inspired | DR20: Intimidation | DS20: Intrigue | DT20: Isolation | DU20: Jealous | DV20: Jealousy | DW20: Journey | DX20: Joy | DY20: Joy In Baking | DZ20: Joyfulreunion | EA20: Kind | EB20: Kindness | EC20: Loneliness | ED20: Loss | EE20: Lostlove | EF20: Love | EG20: Marvel | EH20: Melancholy | EI20: Melodic | EJ20: Mesmerizing | EK20: Mindfulness | EL20: Miscalculation | EM20: Mischievous | EN20: Motivation | EO20: Nature'S Beauty | EP20: Negative | EQ20: Neutral | ER20: Nostalgia | ES20: Numbness | ET20: Obstacle | EU20: Ocean'S Freedom | EV20: Optimism | EW20: Overjoyed | EX20: Overwhelmed | EY20: Pensive | EZ20: Playful | FA20: Playfuljoy | FB20: Positive | FC20: Positivity | FD20: Pressure | FE20: Pride | FF20: Proud | FG20: Radiance | FH20: Reflection | FI20: Regret | FJ20: Rejuvenation | FK20: Relief | FL20: Renewed Effort | FM20: Resentment | FN20: Resilience | FO20: Reverence | FP20: Romance | FQ20: Ruins | FR20: Runway Creativity | FS20: Sad | FT20: Sadness | FU20: Satisfaction | FV20: Serenity | FW20: Shame | FX20: Solace | FY20: Solitude | FZ20: Sorrow | GA20: Spark | GB20: Success | GC20: Suffering | GD20: Surprise | GE20: Suspense | GF20: Sympathy | GG20: Tenderness | GH20: Thrill | GI20: Thrilling Journey | GJ20: Touched | GK20: Tranquility | GL20: Triumph | GM20: Vibrancy | GN20: Whimsy | GO20: Whispers Of The Past | GP20: Winter Magic | GQ20: Wonder | GR20: Wonderment | GS20: Yearning | GT20: Zest | GU20: Grand Total
A21: Artisticburst | B21: 1 | G21: CHINA | H21: 60 | I21: 18 | K21: Facebook | L21: 4 | M21: 3 | P21: 1 | T21: 2 | U21: 1 | X21: 1 | AC21: 5 | AD21: 2 | AE21: 2 | AF21: 2 | AG21: 2 | AJ21: 1 | AL21: 1 | AO21: 1 | AP21: 1 | AS21: 2 | AT21: 1 | AV21: 2 | AW21: 2 | AZ21: 6 | BF21: 6 | BG21: 1 | BH21: 1 | BI21: 2 | BJ21: 4 | BL21: 3 | BS21: 1 | BT21: 2 | BU21: 1 | BV21: 2 | BW21: 1 | BY21: 2 | CA21: 1 | CC21: 1 | CD21: 2 | CE21: 2 | CF21: 1 | CH21: 1 | CI21: 3 | CJ21: 11 | CN21: 1 | CO21: 1 | CS21: 2 | CT21: 1 | CU21: 2 | CW21: 1 | CX21: 7 | CY21: 6 | CZ21: 1 | DA21: 4 | DB21: 1 | DC21: 2 | DH21: 2 | DI21: 1 | DJ21: 1 | DL21: 1 | DN21: 3 | DP21: 2 | DQ21: 2 | DR21: 1 | DU21: 1 | DV21: 1 | DX21: 20 | EA21: 1 | EB21: 1 | EC21: 3 | EE21: 1 | EH21: 2 | EN21: 1 | EQ21: 6 | ER21: 4 | ES21: 1 | EU21: 1 | EX21: 3 | EZ21: 4 | FA21: 1 | FB21: 16 | FD21: 1 | FE21: 1 | FG21: 2 | FH21: 1 | FI21: 1 | FM21: 1 | FN21: 1 | FS21: 3 | FT21: 2 | FV21: 5 | FW21: 2 | FX21: 1 | GA21: 1 | GC21: 1 | GD21: 1 | GE21: 1 | GG21: 2 | GH21: 1 | GK21: 1 | GL21: 1 | GP21: 1 | GS21: 1 | GU21: 231
A22: Awe | B22: 9 | G22: COLOMBIA | H22: 35 | I22: 28 | K22: Instagram | L22: 2 | N22: 2 | R22: 2 | T22: 2 | U22: 2 | W22: 2 | X22: 1 | Z22: 1 | AA22: 2 | AC22: 3 | AD22: 2 | AE22: 2 | AG22: 2 | AH22: 1 | AI22: 1 | AJ22: 2 | AN22: 1 | AR22: 1 | AS22: 2 | AT22: 2 | AU22: 1 | AV22: 1 | AW22: 4 | AX22: 1 | AY22: 1 | AZ22: 7 | BA22: 2 | BC22: 1 | BD22: 1 | BF22: 6 | BJ22: 4 | BK22: 1 | BL22: 1 | BM22: 2 | BP22: 2 | BQ22: 2 | BT22: 3 | BV22: 3 | BW22: 1 | BX22: 1 | BY22: 1 | BZ22: 3 | CA22: 3 | CE22: 4 | CH22: 1 | CI22: 4 | CJ22: 13 | CK22: 1 | CL22: 1 | CM22: 2 | CQ22: 1 | CR22: 1 | CS22: 2 | CT22: 3 | CV22: 1 | CW22: 2 | CX22: 4 | CY22: 2 | CZ22: 2 | DA22: 6 | DB22: 2 | DC22: 2 | DD22: 1 | DE22: 1 | DF22: 1 | DG22: 1 | DH22: 1 | DI22: 4 | DN22: 2 | DO22: 1 | DP22: 1 | DT22: 2 | DV22: 1 | DW22: 1 | DX22: 14 | DY22: 1 | DZ22: 1 | EC22: 2 | ED22: 1 | EG22: 1 | EH22: 2 | EK22: 1 | EL22: 1 | EM22: 1 | EO22: 1 | EP22: 1 | EQ22: 6 | ER22: 4 | ES22: 3 | EV22: 1 | EX22: 1 | EZ22: 2 | FB22: 16 | FC22: 1 | FE22: 3 | FH22: 1 | FI22: 2 | FK22: 1 | FM22: 1 | FO22: 2 | FP22: 1 | FR22: 1 | FS22: 3 | FV22: 4 | FY22: 1 | FZ22: 1 | GB22: 1 | GD22: 4 | GF22: 1 | GH22: 2 | GJ22: 1 | GK22: 1 | GM22: 1 | GN22: 2 | GQ22: 3 | GS22: 1 | GT22: 1 | GU22: 258
A23: Bad | B23: 6 | G23: CZECH REPUBLIC | H23: 40 | I23: 18 | K23: Twitter | L23: 2 | N23: 2 | O23: 2 | Q23: 3 | S23: 1 | T23: 2 | V23: 2 | W23: 1 | Y23: 1 | Z23: 1 | AA23: 2 | AB23: 1 | AC23: 1 | AD23: 2 | AE23: 1 | AF23: 1 | AG23: 1 | AJ23: 1 | AK23: 1 | AL23: 3 | AM23: 2 | AQ23: 1 | AT23: 1 | AW23: 2 | AY23: 1 | AZ23: 6 | BB23: 1 | BC23: 2 | BE23: 1 | BF23: 4 | BI23: 2 | BJ23: 3 | BL23: 3 | BM23: 1 | BN23: 2 | BO23: 2 | BP23: 3 | BQ23: 1 | BR23: 1 | BT23: 2 | BV23: 3 | BZ23: 2 | CB23: 1 | CE23: 1 | CF23: 2 | CG23: 1 | CJ23: 13 | CL23: 1 | CN23: 2 | CP23: 1 | CQ23: 2 | CS23: 1 | CT23: 2 | CU23: 2 | CW23: 1 | CX23: 7 | CY23: 1 | CZ23: 2 | DA23: 4 | DC23: 2 | DE23: 2 | DG23: 1 | DH23: 2 | DI23: 4 | DK23: 1 | DM23: 1 | DN23: 1 | DP23: 3 | DQ23: 3 | DR23: 1 | DS23: 1 | DU23: 2 | DV23: 1 | DX23: 10 | EA23: 2 | EC23: 4 | ED23: 1 | EF23: 3 | EH23: 2 | EI23: 1 | EJ23: 1 | EM23: 1 | EP23: 3 | EQ23: 6 | ER23: 3 | ES23: 2 | ET23: 1 | EW23: 1 | EY23: 1 | FB23: 13 | FE23: 3 | FF23: 4 | FH23: 2 | FI23: 3 | FJ23: 2 | FL23: 1 | FM23: 1 | FN23: 1 | FO23: 2 | FQ23: 1 | FS23: 3 | FU23: 3 | FV23: 6 | FW23: 1 | FZ23: 1 | GD23: 1 | GG23: 2 | GH23: 1 | GI23: 1 | GO23: 1 | GR23: 1 | GT23: 1 | GU23: 243
A24: Betrayal | B24: 5 | G24: DENMARK | H24: 70 | I24: 20 | K24: Grand Total | L24: 8 | M24: 3 | N24: 4 | O24: 2 | P24: 1 | Q24: 3 | R24: 2 | S24: 1 | T24: 6 | U24: 3 | V24: 2 | W24: 3 | X24: 2 | Y24: 1 | Z24: 2 | AA24: 4 | AB24: 1 | AC24: 9 | AD24: 6 | AE24: 5 | AF24: 3 | AG24: 5 | AH24: 1 | AI24: 1 | AJ24: 4 | AK24: 1 | AL24: 4 | AM24: 2 | AN24: 1 | AO24: 1 | AP24: 1 | AQ24: 1 | AR24: 1 | AS24: 4 | AT24: 4 | AU24: 1 | AV24: 3 | AW24: 8 | AX24: 1 | AY24: 2 | AZ24: 19 | BA24: 2 | BB24: 1 | BC24: 3 | BD24: 1 | BE24: 1 | BF24: 16 | BG24: 1 | BH24: 1 | BI24: 4 | BJ24: 11 | BK24: 1 | BL24: 7 | BM24: 3 | BN24: 2 | BO24: 2 | BP24: 5 | BQ24: 3 | BR24: 1 | BS24: 1 | BT24: 7 | BU24: 1 | BV24: 8 | BW24: 2 | BX24: 1 | BY24: 3 | BZ24: 5 | CA24: 4 | CB24: 1 | CC24: 1 | CD24: 2 | CE24: 7 | CF24: 3 | CG24: 1 | CH24: 2 | CI24: 7 | CJ24: 37 | CK24: 1 | CL24: 2 | CM24: 2 | CN24: 3 | CO24: 1 | CP24: 1 | CQ24: 3 | CR24: 1 | CS24: 5 | CT24: 6 | CU24: 4 | CV24: 1 | CW24: 4 | CX24: 18 | CY24: 9 | CZ24: 5 | DA24: 14 | DB24: 3 | DC24: 6 | DD24: 1 | DE24: 3 | DF24: 1 | DG24: 2 | DH24: 5 | DI24: 9 | DJ24: 1 | DK24: 1 | DL24: 1 | DM24: 1 | DN24: 6 | DO24: 1 | DP24: 6 | DQ24: 5 | DR24: 2 | DS24: 1 | DT24: 2 | DU24: 3 | DV24: 3 | DW24: 1 | DX24: 44 | DY24: 1 | DZ24: 1 | EA24: 3 | EB24: 1 | EC24: 9 | ED24: 2 | EE24: 1 | EF24: 3 | EG24: 1 | EH24: 6 | EI24: 1 | EJ24: 1 | EK24: 1 | EL24: 1 | EM24: 2 | EN24: 1 | EO24: 1 | EP24: 4 | EQ24: 18 | ER24: 11 | ES24: 6 | ET24: 1 | EU24: 1 | EV24: 1 | EW24: 1 | EX24: 4 | EY24: 1 | EZ24: 6 | FA24: 1 | FB24: 45 | FC24: 1 | FD24: 1 | FE24: 7 | FF24: 4 | FG24: 2 | FH24: 4 | FI24: 6 | FJ24: 2 | FK24: 1 | FL24: 1 | FM24: 3 | FN24: 2 | FO24: 4 | FP24: 1 | FQ24: 1 | FR24: 1 | FS24: 9 | FT24: 2 | FU24: 3 | FV24: 15 | FW24: 3 | FX24: 1 | FY24: 1 | FZ24: 2 | GA24: 1 | GB24: 1 | GC24: 1 | GD24: 6 | GE24: 1 | GF24: 1 | GG24: 4 | GH24: 4 | GI24: 1 | GJ24: 1 | GK24: 2 | GL24: 1 | GM24: 1 | GN24: 2 | GO24: 1 | GP24: 1 | GQ24: 3 | GR24: 1 | GS24: 2 | GT24: 2 | GU24: 732
A25: Bitter | B25: 3 | G25: FRANCE | H25: 51.25 | I25: 23.25
A26: Bitterness | B26: 5 | G26: GERMANY | H26: 46.428571 | I26: 24.214286
A27: Bittersweet | B27: 1 | G27: GREECE | H27: 43 | I27: 22.2
A28: Blessed | B28: 1 | G28: INDIA | H28: 38.7 | I28: 19.057143
A29: Boredom | B29: 4 | G29: IRELAND | H29: 55 | I29: 25
A30: Breakthrough | B30: 1 | G30: ITALY | H30: 57.272727 | I30: 23.545455
A31: Calmness | B31: 4 | G31: JAMAICA | H31: 70 | I31: 30
A32: Captivation | B32: 2 | G32: JAPAN | H32: 49 | I32: 26.2
A33: Celebration | B33: 1 | G33: JORDAN | H33: 45 | I33: 30
A34: Celestial Wonder | B34: 1 | G34: KENYA | H34: 60 | I34: 22
A35: Challenge | B35: 1 | G35: MALDIVES | H35: 50 | I35: 22
A36: Charm | B36: 1 | G36: NETHERLANDS | H36: 36.25 | I36: 26.75
... A48: Creativity | B48: 3 | G48: Grand Total | H48: 42.878415 | I48: 21.508197
A49: Culinary Adventure | B49: 1
A50: Culinaryodyssey | B50: 1
A51: Curiosity | B51: 16
A52: Darkness | B52: 1
...

Sheet L2 T2 - Pivot Charts
A1: Task 2 : Pivot Charts - Social Media Sentiment Dataset
B3: Chart 1 : Sentiment Distribution | J3: Chart 2 : Platform Share
B21: This chart shows the distribution of social media posts across different sentiment categories | J21: This chart shows the percentage share of posts across Twitter, Instagram and Facebook
F23: Chart 3 : Posts Over Time
E40: This chart shows how post volume changed across different months of the year
